Workbook

Sheet Masterf
C1: W35 -45 | D1: W35 -49 | E1: W35 -55 | F1: W35 -59 | G1: W35 -64 | H1: W35 -71 | I1: W35 -76 | J1: W35 -81 | K1: W35 -87 | L1: W35 >87 | M1: W40 -45 | N1: W40 -49 | O1: W40 -55 | P1: W40 -59 | Q1: W40 -64 | R1: W40 -71 | S1: W40 -76 | T1: W40 -81 | U1: W40 -87 | V1: W40 >87 | W1: W45 -45 | X1: W45 -49 | Y1: W45 -55 | Z1: W45 -59 | AA1: W45 -64 | AB1: W45 -71 | AC1: W45 -76 | AD1: W45 -81 | AE1: W45 -87 | AF1: W45 >87 | AG1: W50 -45 | AH1: W50 -49 | AI1: W50 -55 | AJ1: W50 -59 | AK1: W50 -64 | AL1: W50 -71 | AM1: W50 -76 | AN1: W50 -81 | AO1: W50 -87 | AP1: W50 >87 | AQ1: W55 -45 | AR1: W55 -49 | AS1: W55 -55 | AT1: W55 -59 | AU1: W55 -64 | AV1: W55 -71 | AW1: W55 -76 | AX1: W55 -81 | AY1: W55 -87 | AZ1: W55 >87 | BA1: W60 -45 | BB1: W60 -49 | BC1: W60 -55 | BD1: W60 -59 | BE1: W60 -64 | BF1: W60 -71 | BG1: W60 -76 | BH1: W60 -81 | BI1: W60 -87 | BJ1: W60 >87 | BK1: W65 -45 | BL1: W65 -49 | BM1: W65 -55 | BN1: W65 -59 | BO1: W65 -64 | BP1: W65 -71 | BQ1: W65 -76 | BR1: W65 -81 | BS1: W65 -87 | BT1: W65 >87 | BU1: W70 -45 | BV1: W70 -49 | BW1: W70 -55 | BX1: W70 -59 | BY1: W70 -64 | BZ1: W70 -71 | CA1: W70 -76 | CB1: W70 -81 | CC1: W70 -87 | CD1: W70 >87
B3: REGION | C3: 50 | D3: 55 | E3: 60 | F3: 65 | G3: 70 | H3: 74 | I3: 77 | J3: 80 | K3: 85 | L3: 90 | M3: 47 | N3: 50 | O3: 55 | P3: 30 | Q3: 62 | R3: 65 | S3: 67 | T3: 70 | U3: 75 | V3: 80 | W3: 45 | X3: 47 | Y3: 52 | Z3: 55 | AA3: 57 | AB3: 60 | AC3: 62 | AD3: 65 | AE3: 70 | AF3: 75 | AG3: 42 | AH3: 45 | AI3: 47 | AJ3: 52 | AK3: 55 | AL3: 57 | AM3: 60 | AN3: 62 | AO3: 65 | AP3: 67 | AQ3: 38 | AR3: 42 | AS3: 45 | AT3: 47 | AU3: 50 | AV3: 52 | AW3: 55 | AX3: 57 | AY3: 60 | AZ3: 62 | BA3: 36 | BB3: 40 | BC3: 42 | BD3: 45 | BE3: 47 | BF3: 50 | BG3: 52 | BH3: 55 | BI3: 57 | BJ3: 60 | BK3: 33 | BL3: 37 | BM3: 40 | BN3: 42 | BO3: 45 | BP3: 47 | BQ3: 50 | BR3: 52 | BS3: 55 | BT3: 57 | BU3: 30 | BV3: 34 | BW3: 38 | BX3: 40 | BY3: 42 | BZ3: 45 | CA3: 47 | CB3: 50 | CC3: 52 | CD3: 54
B4: FRANCE | C4: 65 | D4: 72 | E4: 80 | F4: 85 | G4: 90 | H4: 94 | I4: 97 | J4: 100 | K4: 105 | L4: 110 | M4: 60 | N4: 67 | O4: 72 | P4: 77 | Q4: 82 | R4: 87 | S4: 90 | T4: 92 | U4: 95 | V4: 100 | W4: 56 | X4: 62 | Y4: 67 | Z4: 72 | AA4: 77 | AB4: 80 | AC4: 82 | AD4: 85 | AE4: 90 | AF4: 95 | AG4: 52 | AH4: 57 | AI4: 62 | AJ4: 67 | AK4: 70 | AL4: 72 | AM4: 75 | AN4: 80 | AO4: 82 | AP4: 85 | AQ4: 46 | AR4: 50 | AS4: 55 | AT4: 60 | AU4: 65 | AV4: 67 | AW4: 70 | AX4: 75 | AY4: 77 | AZ4: 80 | BA4: 44 | BB4: 47 | BC4: 50 | BD4: 55 | BE4: 60 | BF4: 62 | BG4: 65 | BH4: 67 | BI4: 70 | BJ4: 73 | BK4: 40 | BL4: 43 | BM4: 47 | BN4: 50 | BO4: 52 | BP4: 57 | BQ4: 60 | BR4: 62 | BS4: 64 | BT4: 66 | BU4: 36 | BV4: 39 | BW4: 42 | BX4: 45 | BY4: 48 | BZ4: 50 | CA4: 52 | CB4: 54 | CC4: 56 | CD4: 58
B5: EUROPE | C5: 79 | D5: 85 | E5: 93 | F5: 98 | G5: 104 | H5: 111 | I5: 115 | J5: 119 | K5: 123 | L5: 123 | M5: 74 | N5: 80 | O5: 88 | P5: 93 | Q5: 98 | R5: 105 | S5: 109 | T5: 112 | U5: 116 | V5: 119 | W5: 70 | X5: 76 | Y5: 83 | Z5: 87 | AA5: 92 | AB5: 99 | AC5: 102 | AD5: 106 | AE5: 109 | AF5: 112 | AG5: 66 | AH5: 71 | AI5: 78 | AJ5: 82 | AK5: 87 | AL5: 92 | AM5: 96 | AN5: 99 | AO5: 102 | AP5: 105 | AQ5: 56 | AR5: 61 | AS5: 66 | AT5: 70 | AU5: 74 | AV5: 79 | AW5: 82 | AX5: 85 | AY5: 87 | AZ5: 90 | BA5: 48 | BB5: 51 | BC5: 57 | BD5: 60 | BE5: 63 | BF5: 67 | BG5: 70 | BH5: 72 | BI5: 74 | BJ5: 77 | BK5: 43 | BL5: 46 | BM5: 51 | BN5: 54 | BO5: 57 | BP5: 61 | BQ5: 63 | BR5: 65 | BS5: 67 | BT5: 69 | BU5: 38 | BV5: 41 | BW5: 45 | BX5: 48 | BY5: 51 | BZ5: 54 | CA5: 56 | CB5: 58 | CC5: 60 | CD5: 61
B6: MONDE | C6: 93 | D6: 99 | E6: 108 | F6: 114 | G6: 119 | H6: 127 | I6: 131 | J6: 135 | K6: 139 | L6: 147 | M6: 88 | N6: 94 | O6: 102 | P6: 107 | Q6: 113 | R6: 119 | S6: 124 | T6: 127 | U6: 131 | V6: 139 | W6: 78 | X6: 83 | Y6: 91 | Z6: 95 | AA6: 100 | AB6: 106 | AC6: 110 | AD6: 113 | AE6: 116 | AF6: 123 | AG6: 71 | AH6: 76 | AI6: 82 | AJ6: 86 | AK6: 91 | AL6: 96 | AM6: 100 | AN6: 102 | AO6: 106 | AP6: 112 | AQ6: 62 | AR6: 67 | AS6: 73 | AT6: 76 | AU6: 80 | AV6: 85 | AW6: 88 | AX6: 91 | AY6: 94 | AZ6: 99 | BA6: 55 | BB6: 59 | BC6: 65 | BD6: 68 | BE6: 71 | BF6: 76 | BG6: 78 | BH6: 80 | BI6: 83 | BJ6: 88 | BK6: 48 | BL6: 52 | BM6: 56 | BN6: 59 | BO6: 62 | BP6: 66 | BQ6: 68 | BR6: 70 | BS6: 72 | BT6: 76 | BU6: 42 | BV6: 45 | BW6: 49 | BX6: 51 | BY6: 54 | BZ6: 57 | CA6: 59 | CB6: 61 | CC6: 62 | CD6: 66
B7: INTERNATIONAL B | C7: 1000 | D7: 1000 | E7: 1000 | F7: 1000 | G7: 1000 | H7: 1000 | I7: 1000 | J7: 1000 | K7: 1000 | L7: 1000 | M7: 1000 | N7: 1000 | O7: 1000 | P7: 1000 | Q7: 1000 | R7: 1000 | S7: 1000 | T7: 1000 | U7: 1000 | V7: 1000 | W7: 1000 | X7: 1000 | Y7: 1000 | Z7: 1000 | AA7: 1000 | AB7: 1000 | AC7: 1000 | AD7: 1000 | AE7: 1000 | AF7: 1000 | AG7: 1000 | AH7: 1000 | AI7: 1000 | AJ7: 1000 | AK7: 1000 | AL7: 1000 | AM7: 1000 | AN7: 1000 | AO7: 1000 | AP7: 1000 | AQ7: 1000 | AR7: 1000 | AS7: 1000 | AT7: 1000 | AU7: 1000 | AV7: 1000 | AW7: 1000 | AX7: 1000 | AY7: 1000 | AZ7: 1000 | BA7: 1000 | BB7: 1000 | BC7: 1000 | BD7: 1000 | BE7: 1000 | BF7: 1000 | BG7: 1000 | BH7: 1000 | BI7: 1000 | BJ7: 1000 | BK7: 1000 | BL7: 1000 | BM7: 1000 | BN7: 1000 | BO7: 1000 | BP7: 1000 | BQ7: 1000 | BR7: 1000 | BS7: 1000 | BT7: 1000 | BU7: 1000 | BV7: 1000 | BW7: 1000 | BX7: 1000 | BY7: 1000 | BZ7: 1000 | CA7: 1000 | CB7: 1000 | CC7: 1000 | CD7: 1000
B8: INTERNATIONAL A | C8: 1000 | D8: 1000 | E8: 1000 | F8: 1000 | G8: 1000 | H8: 1000 | I8: 1000 | J8: 1000 | K8: 1000 | L8: 1000 | M8: 1000 | N8: 1000 | O8: 1000 | P8: 1000 | Q8: 1000 | R8: 1000 | S8: 1000 | T8: 1000 | U8: 1000 | V8: 1000 | W8: 1000 | X8: 1000 | Y8: 1000 | Z8: 1000 | AA8: 1000 | AB8: 1000 | AC8: 1000 | AD8: 1000 | AE8: 1000 | AF8: 1000 | AG8: 1000 | AH8: 1000 | AI8: 1000 | AJ8: 1000 | AK8: 1000 | AL8: 1000 | AM8: 1000 | AN8: 1000 | AO8: 1000 | AP8: 1000 | AQ8: 1000 | AR8: 1000 | AS8: 1000 | AT8: 1000 | AU8: 1000 | AV8: 1000 | AW8: 1000 | AX8: 1000 | AY8: 1000 | AZ8: 1000 | BA8: 1000 | BB8: 1000 | BC8: 1000 | BD8: 1000 | BE8: 1000 | BF8: 1000 | BG8: 1000 | BH8: 1000 | BI8: 1000 | BJ8: 1000 | BK8: 1000 | BL8: 1000 | BM8: 1000 | BN8: 1000 | BO8: 1000 | BP8: 1000 | BQ8: 1000 | BR8: 1000 | BS8: 1000 | BT8: 1000 | BU8: 1000 | BV8: 1000 | BW8: 1000 | BX8: 1000 | BY8: 1000 | BZ8: 1000 | CA8: 1000 | CB8: 1000 | CC8: 1000 | CD8: 1000
B9: OLYMPIQUE | C9: 1000 | D9: 1000 | E9: 1000 | F9: 1000 | G9: 1000 | H9: 1000 | I9: 1000 | J9: 1000 | K9: 1000 | L9: 1000 | M9: 1000 | N9: 1000 | O9: 1000 | P9: 1000 | Q9: 1000 | R9: 1000 | S9: 1000 | T9: 1000 | U9: 1000 | V9: 1000 | W9: 1000 | X9: 1000 | Y9: 1000 | Z9: 1000 | AA9: 1000 | AB9: 1000 | AC9: 1000 | AD9: 1000 | AE9: 1000 | AF9: 1000 | AG9: 1000 | AH9: 1000 | AI9: 1000 | AJ9: 1000 | AK9: 1000 | AL9: 1000 | AM9: 1000 | AN9: 1000 | AO9: 1000 | AP9: 1000 | AQ9: 1000 | AR9: 1000 | AS9: 1000 | AT9: 1000 | AU9: 1000 | AV9: 1000 | AW9: 1000 | AX9: 1000 | AY9: 1000 | AZ9: 1000 | BA9: 1000 | BB9: 1000 | BC9: 1000 | BD9: 1000 | BE9: 1000 | BF9: 1000 | BG9: 1000 | BH9: 1000 | BI9: 1000 | BJ9: 1000 | BK9: 1000 | BL9: 1000 | BM9: 1000 | BN9: 1000 | BO9: 1000 | BP9: 1000 | BQ9: 1000 | BR9: 1000 | BS9: 1000 | BT9: 1000 | BU9: 1000 | BV9: 1000 | BW9: 1000 | BX9: 1000 | BY9: 1000 | BZ9: 1000 | CA9: 1000 | CB9: 1000 | CC9: 1000 | CD9: 1000
G11: W35 | H11: W40 | I11: W45 | J11: W50 | K11: W55 | L11: W60 | M11: W65 | N11: W70
F12: 20.01 | G12: W35 -45 | H12: W40 -45 | I12: W45 -45 | J12: W50 -45 | K12: W55 -45 | L12: W60 -45 | M12: W65 -45 | N12: W70 -45
F13: 45.01 | G13: W35 -49 | H13: W40 -49 | I13: W45 -49 | J13: W50 -49 | K13: W55 -49 | L13: W60 -49 | M13: W65 -49 | N13: W70 -49
F14: 49.01 | G14: W35 -55 | H14: W40 -55 | I14: W45 -55 | J14: W50 -55 | K14: W55 -55 | L14: W60 -55 | M14: W65 -55 | N14: W70 -55
F15: 55.01 | G15: W35 -59 | H15: W40 -59 | I15: W45 -59 | J15: W50 -59 | K15: W55 -59 | L15: W60 -59 | M15: W65 -59 | N15: W70 -59
F16: 59.01 | G16: W35 -64 | H16: W40 -64 | I16: W45 -64 | J16: W50 -64 | K16: W55 -64 | L16: W60 -64 | M16: W65 -64 | N16: W70 -64
F17: 64.01 | G17: W35 -71 | H17: W40 -71 | I17: W45 -71 | J17: W50 -71 | K17: W55 -71 | L17: W60 -71 | M17: W65 -71 | N17: W70 -71
F18: 71.01 | G18: W35 -76 | H18: W40 -76 | I18: W45 -76 | J18: W50 -76 | K18: W55 -76 | L18: W60 -76 | M18: W65 -76 | N18: W70 -76
F19: 76.01 | G19: W35 -81 | H19: W40 -81 | I19: W45 -81 | J19: W50 -81 | K19: W55 -81 | L19: W60 -81 | M19: W65 -81 | N19: W70 -81
F20: 81.01 | G20: W35 -87 | H20: W40 -87 | I20: W45 -87 | J20: W50 -87 | K20: W55 -87 | L20: W60 -87 | M20: W65 -87 | N20: W70 -87
F21: 87.01 | G21: W35 >87 | H21: W40 >87 | I21: W45 >87 | J21: W50 >87 | K21: W55 >87 | L21: W60 >87 | M21: W65 >87 | N21: W70 >87

Sheet Masterh
C1: M35 -55 | D1: M35 -61 | E1: M35 -67 | F1: M35 -73 | G1: M35 -81 | H1: M35 -89 | I1: M35 -96 | J1: M35 -102 | K1: M35 -109 | L1: M35 >109 | M1: M40 -55 | N1: M40 -61 | O1: M40 -67 | P1: M40 -73 | Q1: M40 -81 | R1: M40 -89 | S1: M40 -96 | T1: M40 -102 | U1: M40 -109 | V1: M40 >109 | W1: M45 -55 | X1: M45 -61 | Y1: M45 -67 | Z1: M45 -73 | AA1: M45 -81 | AB1: M45 -89 | AC1: M45 -96 | AD1: M45 -102 | AE1: M45 -109 | AF1: M45 >109 | AG1: M50 -55 | AH1: M50 -61 | AI1: M50 -67 | AJ1: M50 -73 | AK1: M50 -81 | AL1: M50 -89 | AM1: M50 -96 | AN1: M50 -102 | AO1: M50 -109 | AP1: M50 >109 | AQ1: M55 -55 | AR1: M55 -61 | AS1: M55 -67 | AT1: M55 -73 | AU1: M55 -81 | AV1: M55 -89 | AW1: M55 -96 | AX1: M55 -102 | AY1: M55 -109 | AZ1: M55 >109 | BA1: M60 -55 | BB1: M60 -61 | BC1: M60 -67 | BD1: M60 -73 | BE1: M60 -81 | BF1: M60 -89 | BG1: M60 -96 | BH1: M60 -102 | BI1: M60 -109 | BJ1: M60 >109 | BK1: M65 -55 | BL1: M65 -61 | BM1: M65 -67 | BN1: M65 -73 | BO1: M65 -81 | BP1: M65 -89 | BQ1: M65 -96 | BR1: M65 -102 | BS1: M65 -109 | BT1: M65 >109 | BU1: M70 -55 | BV1: M70 -61 | BW1: M70 -67 | BX1: M70 -73 | BY1: M70 -81 | BZ1: M70 -89 | CA1: M70 -96 | CB1: M70 -102 | CC1: M70 -109 | CD1: M70 >109 | CE1: M75 -55 | CF1: M75 -61 | CG1: M75 -67 | CH1: M75 -73 | CI1: M75 -81 | CJ1: M75 -89 | CK1: M75 -96 | CL1: M75 -102 | CM1: M75 -109 | CN1: M75 >109 | CO1: M80 -55 | CP1: M80 -61 | CQ1: M80 -67 | CR1: M80 -73 | CS1: M80 -81 | CT1: M80 -89 | CU1: M80 -96 | CV1: M80 -102 | CW1: M80 -109 | CX1: M80 >109
B3: REGION | C3: 115 | D3: 132 | E3: 147 | F3: 160 | G3: 170 | H3: 180 | I3: 185 | J3: 190 | K3: 195 | L3: 200 | M3: 110 | N3: 125 | O3: 140 | P3: 150 | Q3: 160 | R3: 170 | S3: 175 | T3: 180 | U3: 185 | V3: 190 | W3: 105 | X3: 117 | Y3: 130 | Z3: 140 | AA3: 150 | AB3: 160 | AC3: 165 | AD3: 170 | AE3: 172 | AF3: 175 | AG3: 95 | AH3: 107 | AI3: 120 | AJ3: 127 | AK3: 135 | AL3: 145 | AM3: 150 | AN3: 155 | AO3: 160 | AP3: 165 | AQ3: 82 | AR3: 92 | AS3: 105 | AT3: 115 | AU3: 120 | AV3: 125 | AW3: 130 | AX3: 135 | AY3: 140 | AZ3: 145 | BA3: 72 | BB3: 82 | BC3: 92 | BD3: 100 | BE3: 105 | BF3: 100 | BG3: 115 | BH3: 120 | BI3: 122 | BJ3: 130 | BK3: 55 | BL3: 67 | BM3: 75 | BN3: 80 | BO3: 90 | BP3: 95 | BQ3: 100 | BR3: 102 | BS3: 105 | BT3: 110 | BU3: 47 | BV3: 55 | BW3: 60 | BX3: 65 | BY3: 70 | BZ3: 72 | CA3: 77 | CB3: 80 | CC3: 85 | CD3: 90 | CE3: 42 | CF3: 50 | CG3: 55 | CH3: 57 | CI3: 60 | CJ3: 62 | CK3: 65 | CL3: 70 | CM3: 75 | CN3: 77 | CO3: 40 | CP3: 45 | CQ3: 47 | CR3: 50 | CS3: 52 | CT3: 55 | CU3: 57 | CV3: 60 | CW3: 62 | CX3: 65 | CY3: REGIONAL
B4: FRANCE | C4: 140 | D4: 155 | E4: 170 | F4: 182 | G4: 192 | H4: 202 | I4: 210 | J4: 214 | K4: 218 | L4: 222 | M4: 132 | N4: 146 | O4: 160 | P4: 170 | Q4: 180 | R4: 190 | S4: 197 | T4: 202 | U4: 206 | V4: 210 | W4: 125 | X4: 137 | Y4: 150 | Z4: 160 | AA4: 170 | AB4: 180 | AC4: 185 | AD4: 190 | AE4: 194 | AF4: 197 | AG4: 115 | AH4: 128 | AI4: 140 | AJ4: 147 | AK4: 157 | AL4: 167 | AM4: 172 | AN4: 177 | AO4: 180 | AP4: 182 | AQ4: 100 | AR4: 112 | AS4: 120 | AT4: 127 | AU4: 137 | AV4: 143 | AW4: 150 | AX4: 153 | AY4: 157 | AZ4: 160 | BA4: 90 | BB4: 100 | BC4: 110 | BD4: 117 | BE4: 125 | BF4: 130 | BG4: 137 | BH4: 140 | BI4: 143 | BJ4: 147 | BK4: 75 | BL4: 87 | BM4: 95 | BN4: 100 | BO4: 107 | BP4: 113 | BQ4: 117 | BR4: 120 | BS4: 123 | BT4: 127 | BU4: 64 | BV4: 72 | BW4: 80 | BX4: 85 | BY4: 90 | BZ4: 95 | CA4: 100 | CB4: 102 | CC4: 105 | CD4: 107 | CE4: 57 | CF4: 62 | CG4: 70 | CH4: 75 | CI4: 77 | CJ4: 82 | CK4: 85 | CL4: 87 | CM4: 90 | CN4: 92 | CO4: 50 | CP4: 54 | CQ4: 57 | CR4: 60 | CS4: 63 | CT4: 65 | CU4: 67 | CV4: 70 | CW4: 72 | CX4: 75 | CY4: France
B5: EUROPE | C5: 153 | D5: 165 | E5: 176 | F5: 186 | G5: 197 | H5: 207 | I5: 214 | J5: 219 | K5: 224 | L5: 231 | M5: 144 | N5: 156 | O5: 166 | P5: 176 | Q5: 186 | R5: 195 | S5: 202 | T5: 207 | U5: 211 | V5: 218 | W5: 136 | X5: 147 | Y5: 157 | Z5: 165 | AA5: 175 | AB5: 184 | AC5: 190 | AD5: 195 | AE5: 199 | AF5: 205 | AG5: 127 | AH5: 138 | AI5: 147 | AJ5: 155 | AK5: 164 | AL5: 172 | AM5: 178 | AN5: 182 | AO5: 187 | AP5: 192 | AQ5: 110 | AR5: 119 | AS5: 127 | AT5: 134 | AU5: 142 | AV5: 149 | AW5: 154 | AX5: 158 | AY5: 161 | AZ5: 166 | BA5: 101 | BB5: 109 | BC5: 116 | BD5: 123 | BE5: 130 | BF5: 136 | BG5: 141 | BH5: 144 | BI5: 148 | BJ5: 152 | BK5: 87 | BL5: 94 | BM5: 101 | BN5: 106 | BO5: 113 | BP5: 118 | BQ5: 122 | BR5: 125 | BS5: 128 | BT5: 132 | BU5: 74 | BV5: 80 | BW5: 86 | BX5: 91 | BY5: 96 | BZ5: 101 | CA5: 104 | CB5: 107 | CC5: 109 | CD5: 112 | CE5: 64 | CF5: 70 | CG5: 74 | CH5: 79 | CI5: 83 | CJ5: 87 | CK5: 90 | CL5: 92 | CM5: 95 | CN5: 97 | CO5: 54 | CP5: 58 | CQ5: 62 | CR5: 66 | CS5: 69 | CT5: 73 | CU5: 75 | CV5: 77 | CW5: 79 | CX5: 81 | CY5: EUROPE
B6: MONDE | C6: 170 | D6: 184 | E6: 195 | F6: 206 | G6: 218 | H6: 228 | I6: 235 | J6: 240 | K6: 246 | L6: 250 | M6: 161 | N6: 173 | O6: 184 | P6: 194 | Q6: 205 | R6: 215 | S6: 222 | T6: 227 | U6: 232 | V6: 236 | W6: 149 | X6: 160 | Y6: 171 | Z6: 180 | AA6: 190 | AB6: 199 | AC6: 205 | AD6: 210 | AE6: 215 | AF6: 219 | AG6: 137 | AH6: 148 | AI6: 157 | AJ6: 166 | AK6: 175 | AL6: 183 | AM6: 189 | AN6: 193 | AO6: 198 | AP6: 201 | AQ6: 123 | AR6: 133 | AS6: 141 | AT6: 149 | AU6: 157 | AV6: 165 | AW6: 170 | AX6: 174 | AY6: 178 | AZ6: 181 | BA6: 111 | BB6: 120 | BC6: 127 | BD6: 134 | BE6: 142 | BF6: 148 | BG6: 153 | BH6: 156 | BI6: 160 | BJ6: 163 | BK6: 98 | BL6: 106 | BM6: 113 | BN6: 119 | BO6: 125 | BP6: 131 | BQ6: 135 | BR6: 139 | BS6: 142 | BT6: 144 | BU6: 86 | BV6: 92 | BW6: 98 | BX6: 104 | BY6: 109 | BZ6: 114 | CA6: 118 | CB6: 121 | CC6: 124 | CD6: 126 | CE6: 73 | CF6: 79 | CG6: 84 | CH6: 88 | CI6: 93 | CJ6: 97 | CK6: 100 | CL6: 103 | CM6: 105 | CN6: 107 | CO6: 60 | CP6: 64 | CQ6: 68 | CR6: 72 | CS6: 76 | CT6: 80 | CU6: 82 | CV6: 84 | CW6: 86 | CX6: 87 | CY6: MONDE
B7: INTERNATIONAL B | C7: 1000 | D7: 1000 | E7: 1000 | F7: 1000 | G7: 1000 | H7: 1000 | I7: 1000 | J7: 1000 | K7: 1000 | L7: 1000 | M7: 1000 | N7: 1000 | O7: 1000 | P7: 1000 | Q7: 1000 | R7: 1000 | S7: 1000 | T7: 1000 | U7: 1000 | V7: 1000 | W7: 1000 | X7: 1000 | Y7: 1000 | Z7: 1000 | AA7: 1000 | AB7: 1000 | AC7: 1000 | AD7: 1000 | AE7: 1000 | AF7: 1000 | AG7: 1000 | AH7: 1000 | AI7: 1000 | AJ7: 1000 | AK7: 1000 | AL7: 1000 | AM7: 1000 | AN7: 1000 | AO7: 1000 | AP7: 1000 | AQ7: 1000 | AR7: 1000 | AS7: 1000 | AT7: 1000 | AU7: 1000 | AV7: 1000 | AW7: 1000 | AX7: 1000 | AY7: 1000 | AZ7: 1000 | BA7: 1000 | BB7: 1000 | BC7: 1000 | BD7: 1000 | BE7: 1000 | BF7: 1000 | BG7: 1000 | BH7: 1000 | BI7: 1000 | BJ7: 1000 | BK7: 1000 | BL7: 1000 | BM7: 1000 | BN7: 1000 | BO7: 1000 | BP7: 1000 | BQ7: 1000 | BR7: 1000 | BS7: 1000 | BT7: 1000 | BU7: 1000 | BV7: 1000 | BW7: 1000 | BX7: 1000 | BY7: 1000 | BZ7: 1000 | CA7: 1000 | CB7: 1000 | CC7: 1000 | CD7: 1000 | CE7: 1000 | CF7: 1000 | CG7: 1000 | CH7: 1000 | CI7: 1000 | CJ7: 1000 | CK7: 1000 | CL7: 1000 | CM7: 1000 | CN7: 1000 | CO7: 1000 | CP7: 1000 | CQ7: 1000 | CR7: 1000 | CS7: 1000 | CT7: 1000 | CU7: 1000 | CV7: 1000 | CW7: 1000 | CX7: 1000
B8: INTERNATIONAL A | C8: 1000 | D8: 1000 | E8: 1000 | F8: 1000 | G8: 1000 | H8: 1000 | I8: 1000 | J8: 1000 | K8: 1000 | L8: 1000 | M8: 1000 | N8: 1000 | O8: 1000 | P8: 1000 | Q8: 1000 | R8: 1000 | S8: 1000 | T8: 1000 | U8: 1000 | V8: 1000 | W8: 1000 | X8: 1000 | Y8: 1000 | Z8: 1000 | AA8: 1000 | AB8: 1000 | AC8: 1000 | AD8: 1000 | AE8: 1000 | AF8: 1000 | AG8: 1000 | AH8: 1000 | AI8: 1000 | AJ8: 1000 | AK8: 1000 | AL8: 1000 | AM8: 1000 | AN8: 1000 | AO8: 1000 | AP8: 1000 | AQ8: 1000 | AR8: 1000 | AS8: 1000 | AT8: 1000 | AU8: 1000 | AV8: 1000 | AW8: 1000 | AX8: 1000 | AY8: 1000 | AZ8: 1000 | BA8: 1000 | BB8: 1000 | BC8: 1000 | BD8: 1000 | BE8: 1000 | BF8: 1000 | BG8: 1000 | BH8: 1000 | BI8: 1000 | BJ8: 1000 | BK8: 1000 | BL8: 1000 | BM8: 1000 | BN8: 1000 | BO8: 1000 | BP8: 1000 | BQ8: 1000 | BR8: 1000 | BS8: 1000 | BT8: 1000 | BU8: 1000 | BV8: 1000 | BW8: 1000 | BX8: 1000 | BY8: 1000 | BZ8: 1000 | CA8: 1000 | CB8: 1000 | CC8: 1000 | CD8: 1000 | CE8: 1000 | CF8: 1000 | CG8: 1000 | CH8: 1000 | CI8: 1000 | CJ8: 1000 | CK8: 1000 | CL8: 1000 | CM8: 1000 | CN8: 1000 | CO8: 1000 | CP8: 1000 | CQ8: 1000 | CR8: 1000 | CS8: 1000 | CT8: 1000 | CU8: 1000 | CV8: 1000 | CW8: 1000 | CX8: 1000
B9: OLYMPIQUE | C9: 1000 | D9: 1000 | E9: 1000 | F9: 1000 | G9: 1000 | H9: 1000 | I9: 1000 | J9: 1000 | K9: 1000 | L9: 1000 | M9: 1000 | N9: 1000 | O9: 1000 | P9: 1000 | Q9: 1000 | R9: 1000 | S9: 1000 | T9: 1000 | U9: 1000 | V9: 1000 | W9: 1000 | X9: 1000 | Y9: 1000 | Z9: 1000 | AA9: 1000 | AB9: 1000 | AC9: 1000 | AD9: 1000 | AE9: 1000 | AF9: 1000 | AG9: 1000 | AH9: 1000 | AI9: 1000 | AJ9: 1000 | AK9: 1000 | AL9: 1000 | AM9: 1000 | AN9: 1000 | AO9: 1000 | AP9: 1000 | AQ9: 1000 | AR9: 1000 | AS9: 1000 | AT9: 1000 | AU9: 1000 | AV9: 1000 | AW9: 1000 | AX9: 1000 | AY9: 1000 | AZ9: 1000 | BA9: 1000 | BB9: 1000 | BC9: 1000 | BD9: 1000 | BE9: 1000 | BF9: 1000 | BG9: 1000 | BH9: 1000 | BI9: 1000 | BJ9: 1000 | BK9: 1000 | BL9: 1000 | BM9: 1000 | BN9: 1000 | BO9: 1000 | BP9: 1000 | BQ9: 1000 | BR9: 1000 | BS9: 1000 | BT9: 1000 | BU9: 1000 | BV9: 1000 | BW9: 1000 | BX9: 1000 | BY9: 1000 | BZ9: 1000 | CA9: 1000 | CB9: 1000 | CC9: 1000 | CD9: 1000 | CE9: 1000 | CF9: 1000 | CG9: 1000 | CH9: 1000 | CI9: 1000 | CJ9: 1000 | CK9: 1000 | CL9: 1000 | CM9: 1000 | CN9: 1000 | CO9: 1000 | CP9: 1000 | CQ9: 1000 | CR9: 1000 | CS9: 1000 | CT9: 1000 | CU9: 1000 | CV9: 1000 | CW9: 1000 | CX9: 1000
G11: M35 | H11: M40 | I11: M45 | J11: M50 | K11: M55 | L11: M60 | M11: M65 | N11: M70 | O11: M75 | P11: M80
C12: 30 | D12: 1 | F12: 20.01 | G12: M35 -55 | H12: M40 -55 | I12: M45 -55 | J12: M50 -55 | K12: M55 -55 | L12: M60 -55 | M12: M65 -55 | N12: M70 -55 | O12: M75 -55 | P12: M80 -55
C13: 31 | D13: 1.016 | F13: 55.01 | G13: M35 -61 | H13: M40 -61 | I13: M45 -61 | J13: M50 -61 | K13: M55 -61 | L13: M60 -61 | M13: M65 -61 | N13: M70 -61 | O13: M75 -61 | P13: M80 -61
C14: 32 | D14: 1.031 | F14: 61.01 | G14: M35 -67 | H14: M40 -67 | I14: M45 -67 | J14: M50 -67 | K14: M55 -67 | L14: M60 -67 | M14: M65 -67 | N14: M70 -67 | O14: M75 -67 | P14: M80 -67
C15: 33 | D15: 1.046 | F15: 67.01 | G15: M35 -73 | H15: M40 -73 | I15: M45 -73 | J15: M50 -73 | K15: M55 -73 | L15: M60 -73 | M15: M65 -73 | N15: M70 -73 | O15: M75 -73 | P15: M80 -73
C16: 34 | D16: 1.059 | F16: 73.01 | G16: M35 -81 | H16: M40 -81 | I16: M45 -81 | J16: M50 -81 | K16: M55 -81 | L16: M60 -81 | M16: M65 -81 | N16: M70 -81 | O16: M75 -81 | P16: M80 -81
C17: 35 | D17: 1.072 | F17: 81.01 | G17: M35 -89 | H17: M40 -89 | I17: M45 -89 | J17: M50 -89 | K17: M55 -89 | L17: M60 -89 | M17: M65 -89 | N17: M70 -89 | O17: M75 -89 | P17: M80 -89
C18: 36 | D18: 1.083 | F18: 89.05 | G18: M35 -96 | H18: M40 -96 | I18: M45 -96 | J18: M50 -96 | K18: M55 -96 | L18: M60 -96 | M18: M65 -96 | N18: M70 -96 | O18: M75 -96 | P18: M80 -96
C19: 37 | D19: 1.096 | F19: 96.01 | G19: M35 -102 | H19: M40 -102 | I19: M45 -102 | J19: M50 -102 | K19: M55 -102 | L19: M60 -102 | M19: M65 -102 | N19: M70 -102 | O19: M75 -102 | P19: M80 -102
C20: 38 | D20: 1.109 | F20: 102.01 | G20: M35 -109 | H20: M40 -109 | I20: M45 -109 | J20: M50 -109 | K20: M55 -109 | L20: M60 -109 | M20: M65 -109 | N20: M70 -109 | O20: M75 -109 | P20: M80 -109
C21: 39 | D21: 1.122 | F21: 109.01 | G21: M35 >109 | H21: M40 >109 | I21: M45 >109 | J21: M50 >109 | K21: M55 >109 | L21: M60 >109 | M21: M65 >109 | N21: M70 >109 | O21: M75 >109 | P21: M80 >109
C22: 40 | D22: 1.135
C23: 41 | D23: 1.149
C24: 42 | D24: 1.162
C25: 43 | D25: 1.176
C26: 44 | D26: 1.189
C27: 45 | D27: 1.203
C28: 46 | D28: 1.218
C29: 47 | D29: 1.233
C30: 48 | D30: 1.248
C31: 49 | D31: 1.263
C32: 50 | D32: 1.279
C33: 51 | D33: 1.297
... C72: 90 | D72: 4.493

Sheet INDIVIDUEL
D2: COMPETITION MASTER | N2: LIEU | V2: DATE
D3: CHPT OCCITANIE | N3: TOULOUSE | V3: 43388
B5: REG | C5: Licence | D5: Pl | E5: Genre | F5: NOM - Prénom | H5: AN | I5: CLUB | J5: NAT | K5: P.C. | L5: 1 | M5: 2 | N5: 3 | O5: ARR | P5: 1 | Q5: 2 | R5: 3 | S5: EP-J | T5: TOTAL | U5: Serie | V5: Catégorie | W5: IWF | X5: MELTZER | AB5: REG | AC5: REG + | AD5: FRA + | AE5: EUR + | AF5: MON + | AG5: INTB + | AH5: INTA + | AI5: OLY +
AB6: DEB | AC6: REG + | AD6: IRG + | AE6: FED + | AF6: NAT + | AG6: INTB + | AH6: INTA + | AI6: OLY +
B7: BFC | C7: 407932 | D7: 1 | E7: H | H7: 1935 | I7: DIJON | K7: 54 | L7: 25 | O7: =IF(E7="","",IF(MAXA(L7:N7)<=0,0,MAXA(L7:N7))) -> 25 | P7: 50 | S7: =IF(E7="","",IF(MAXA(P7:R7)<=0,0,MAXA(P7:R7))) -> 50 | T7: =IF(E7="","",IF(OR(O7=0,S7=0),0,O7+S7)) -> 75 | U7: =+CONCATENATE(AL7," ",AM7) -> MON + 15 | V7: =IF(E7=0," ",IF(E7="H",AN7,AO7)) -> M80 -55 | W7: =IF(E7=" "," ",IF(E7="H",10^(0.75194503*LOG(K7/175.508)^2)*T7,IF(E7="F",10^(0.783497476* LOG(K7/153.655)^2)*T7,""))) -> 118.06049 | X7: =IF(E7="","",W7*VLOOKUP(2019-H7,Masterh!C$17:D$72,2,FALSE)) -> 351.93832 | AB7: =IF(E7="H",T7-HLOOKUP(V7,Masterh!$C$1:$CX$9,2,FALSE),T7-HLOOKUP(V7,Masterf!$C$1:$CD$9,2,FALSE)) -> 75 | AC7: =IF(E7="H",T7-HLOOKUP(V7,Masterh!$C$1:$CX$9,3,FALSE),T7-HLOOKUP(V7,Masterf!$C$1:$CD$9,3,FALSE)) -> 35 | AD7: =IF(E7="H",T7-HLOOKUP(V7,Masterh!$C$1:$CX$9,4,FALSE),T7-HLOOKUP(V7,Masterf!$C$1:$CD$9,4,FALSE)) -> 25 | AE7: =IF(E7="H",T7-HLOOKUP(V7,Masterh!$C$1:$CX$9,5,FALSE),T7-HLOOKUP(V7,Masterf!$C$1:$CD$9,5,FALSE)) -> 21 | AF7: =IF(E7="H",T7-HLOOKUP(V7,Masterh!$C$1:$CX$9,6,FALSE),T7-HLOOKUP(V7,Masterf!$C$1:$CD$9,6,FALSE)) -> 15 | AG7: =IF(E7="H",T7-HLOOKUP(V7,Masterh!$C$1:$CX$9,7,FALSE),T7-HLOOKUP(V7,Masterf!$C$1:$CD$9,7,FALSE)) -> -925 | AH7: =IF(E7="H",T7-HLOOKUP(V7,Masterh!$C$1:$CX$9,8,FALSE),T7-HLOOKUP(V7,Masterf!$C$1:$CD$9,8,FALSE)) -> -925 | AI7: =IF(E7="H",T7-HLOOKUP(V7,Masterh!$C$1:$CX$9,9,FALSE),T7-HLOOKUP(V7,Masterf!$C$1:$CD$9,9,FALSE)) -> -925 | AJ7: =IF(E7=0," ",IF(AI7>=0,$AI$5,IF(AH7>=0,$AH$5,IF(AG7>=0,$AG$5,IF(AF7>=0,$AF$5,IF(AE7>=0,$AE$5,IF(AD7>=0,$AD$5,IF(AC7>=0,$AC$5,$AB$5)))))))) -> MON + | AL7: =IF(AJ7="","",AJ7) -> MON + | AM7: =IF(E7=0," ",IF(AI7>=0,AI7,IF(AH7>=0,AH7,IF(AG7>=0,AG7,IF(AF7>=0,AF7,IF(AE7>=0,AE7,IF(AD7>=0,AD7,IF(AC7>=0,AC7,AC7)))))))) -> 15 | AN7: =IF(AND(H7<1922),VLOOKUP(K7,Masterh!$F$11:$P$29,11),IF(AND(H7>=1922,H7<1940),VLOOKUP(K7,Masterh!$F$11:$P$29,11),IF(AND(H7>=1940,H7<1945),VLOOKUP(K7,Masterh!$F$11:$P$29,10),IF(AND(H7>=1945,H7<1950),VLOOKUP(K7,Masterh!$F$11:$P$29,9),IF(AND(H7>=1950,H7<1955),VLOOKUP(K7,Masterh!$F$11:$P$29,8),IF(AND(H7>=1955,H7<1960),VLOOKUP(K7,Masterh!$F$11:$P$29,7),IF(AND(H7>=1960,H7<1965),VLOOKUP(K7,Masterh!$F$11:$P$29,6),IF(AND(H7>=1965,H7<1970),VLOOKUP(K7,Masterh!$F$11:$P$29,5),IF(AND(H7>=1970,H7<1975),VLOOKUP(K7,Masterh!$F$11:$P$29,4),IF(AND(H7>=1975,H7<1980),VLOOKUP(K7,Masterh!$F$11:$P$29,3),IF(AND(H7>=1980,H7<1985),VLOOKUP(K7,Masterh!$F$11:$P$29,2),"SENIOR"))))))))))) -> M80 -55 | AO7: =IF(AND(H7<1950),VLOOKUP(K7,Masterf!$F$11:$N$25,9),IF(AND(H7>=1950,H7<1955),VLOOKUP(K7,Masterf!$F$11:$N$25,8),IF(AND(H7>=1955,H7<1960),VLOOKUP(K7,Masterf!$F$11:$N$25,7),IF(AND(H7>=1960,H7<1965),VLOOKUP(K7,Masterf!$F$11:$N$25,6),IF(AND(H7>=1965,H7<1970),VLOOKUP(K7,Masterf!$F$11:$N$25,5),IF(AND(H7>=1970,H7<1975),VLOOKUP(K7,Masterf!$F$11:$N$25,4),IF(AND(H7>=1975,H7<1980),VLOOKUP(K7,Masterf!$F$11:$N$25,3),IF(AND(H7>=1980,H7<1985),VLOOKUP(K7,Masterf!$F$11:$N$25,2),"SENIOR")))))))) -> W70 -55
E8: F | H8: 1980 | K8: 53 | L8: 45 | O8: =IF(E8="","",IF(MAXA(L8:N8)<=0,0,MAXA(L8:N8))) -> 45 | P8: 58 | S8: =IF(E8="","",IF(MAXA(P8:R8)<=0,0,MAXA(P8:R8))) -> 58 | T8: =IF(E8="","",IF(OR(O8=0,S8=0),0,O8+S8)) -> 103 | U8: =+CONCATENATE(AL8," ",AM8) -> EUR + 10 | V8: =IF(E8=0," ",IF(E8="H",AN8,AO8)) -> W35 -55 | W8: =IF(E8=" "," ",IF(E8="H",10^(0.75194503*LOG(K8/175.508)^2)*T8,IF(E8="F",10^(0.783497476* LOG(K8/153.655)^2)*T8,""))) -> 151.44892 | X8: =IF(E8="","",W8*VLOOKUP(2019-H8,Masterh!C$17:D$72,2,FALSE)) -> 169.92569 | AB8: =IF(E8="H",T8-HLOOKUP(V8,Masterh!$C$1:$CX$9,2,FALSE),T8-HLOOKUP(V8,Masterf!$C$1:$CD$9,2,FALSE)) -> 103 | AC8: =IF(E8="H",T8-HLOOKUP(V8,Masterh!$C$1:$CX$9,3,FALSE),T8-HLOOKUP(V8,Masterf!$C$1:$CD$9,3,FALSE)) -> 43 | AD8: =IF(E8="H",T8-HLOOKUP(V8,Masterh!$C$1:$CX$9,4,FALSE),T8-HLOOKUP(V8,Masterf!$C$1:$CD$9,4,FALSE)) -> 23 | AE8: =IF(E8="H",T8-HLOOKUP(V8,Masterh!$C$1:$CX$9,5,FALSE),T8-HLOOKUP(V8,Masterf!$C$1:$CD$9,5,FALSE)) -> 10 | AF8: =IF(E8="H",T8-HLOOKUP(V8,Masterh!$C$1:$CX$9,6,FALSE),T8-HLOOKUP(V8,Masterf!$C$1:$CD$9,6,FALSE)) -> -5 | AG8: =IF(E8="H",T8-HLOOKUP(V8,Masterh!$C$1:$CX$9,7,FALSE),T8-HLOOKUP(V8,Masterf!$C$1:$CD$9,7,FALSE)) -> -897 | AH8: =IF(E8="H",T8-HLOOKUP(V8,Masterh!$C$1:$CX$9,8,FALSE),T8-HLOOKUP(V8,Masterf!$C$1:$CD$9,8,FALSE)) -> -897 | AI8: =IF(E8="H",T8-HLOOKUP(V8,Masterh!$C$1:$CX$9,9,FALSE),T8-HLOOKUP(V8,Masterf!$C$1:$CD$9,9,FALSE)) -> -897 | AJ8: =IF(E8=0," ",IF(AI8>=0,$AI$5,IF(AH8>=0,$AH$5,IF(AG8>=0,$AG$5,IF(AF8>=0,$AF$5,IF(AE8>=0,$AE$5,IF(AD8>=0,$AD$5,IF(AC8>=0,$AC$5,$AB$5)))))))) -> EUR + | AL8: =IF(AJ8="","",AJ8) -> EUR + | AM8: =IF(E8=0," ",IF(AI8>=0,AI8,IF(AH8>=0,AH8,IF(AG8>=0,AG8,IF(AF8>=0,AF8,IF(AE8>=0,AE8,IF(AD8>=0,AD8,IF(AC8>=0,AC8,AC8)))))))) -> 10 | AN8: =IF(AND(H8<1922),VLOOKUP(K8,Masterh!$F$11:$P$29,11),IF(AND(H8>=1922,H8<1940),VLOOKUP(K8,Masterh!$F$11:$P$29,11),IF(AND(H8>=1940,H8<1945),VLOOKUP(K8,Masterh!$F$11:$P$29,10),IF(AND(H8>=1945,H8<1950),VLOOKUP(K8,Masterh!$F$11:$P$29,9),IF(AND(H8>=1950,H8<1955),VLOOKUP(K8,Masterh!$F$11:$P$29,8),IF(AND(H8>=1955,H8<1960),VLOOKUP(K8,Masterh!$F$11:$P$29,7),IF(AND(H8>=1960,H8<1965),VLOOKUP(K8,Masterh!$F$11:$P$29,6),IF(AND(H8>=1965,H8<1970),VLOOKUP(K8,Masterh!$F$11:$P$29,5),IF(AND(H8>=1970,H8<1975),VLOOKUP(K8,Masterh!$F$11:$P$29,4),IF(AND(H8>=1975,H8<1980),VLOOKUP(K8,Masterh!$F$11:$P$29,3),IF(AND(H8>=1980,H8<1985),VLOOKUP(K8,Masterh!$F$11:$P$29,2),"SENIOR"))))))))))) -> M35 -55 | AO8: =IF(AND(H8<1950),VLOOKUP(K8,Masterf!$F$11:$N$25,9),IF(AND(H8>=1950,H8<1955),VLOOKUP(K8,Masterf!$F$11:$N$25,8),IF(AND(H8>=1955,H8<1960),VLOOKUP(K8,Masterf!$F$11:$N$25,7),IF(AND(H8>=1960,H8<1965),VLOOKUP(K8,Masterf!$F$11:$N$25,6),IF(AND(H8>=1965,H8<1970),VLOOKUP(K8,Masterf!$F$11:$N$25,5),IF(AND(H8>=1970,H8<1975),VLOOKUP(K8,Masterf!$F$11:$N$25,4),IF(AND(H8>=1975,H8<1980),VLOOKUP(K8,Masterf!$F$11:$N$25,3),IF(AND(H8>=1980,H8<1985),VLOOKUP(K8,Masterf!$F$11:$N$25,2),"SENIOR")))))))) -> W35 -55
E9: H | H9: 1975 | K9: 55 | L9: 80 | O9: =IF(E9="","",IF(MAXA(L9:N9)<=0,0,MAXA(L9:N9))) -> 80 | P9: 100 | S9: =IF(E9="","",IF(MAXA(P9:R9)<=0,0,MAXA(P9:R9))) -> 100 | T9: =IF(E9="","",IF(OR(O9=0,S9=0),0,O9+S9)) -> 180 | U9: =+CONCATENATE(AL9," ",AM9) -> MON + 19 | V9: =IF(E9=0," ",IF(E9="H",AN9,AO9)) -> M40 -55 | W9: =IF(E9=" "," ",IF(E9="H",10^(0.75194503*LOG(K9/175.508)^2)*T9,IF(E9="F",10^(0.783497476* LOG(K9/153.655)^2)*T9,""))) -> 279.40149 | X9: =IF(E9="","",W9*VLOOKUP(2019-H9,Masterh!C$17:D$72,2,FALSE)) -> 332.20838 | AB9: =IF(E9="H",T9-HLOOKUP(V9,Masterh!$C$1:$CX$9,2,FALSE),T9-HLOOKUP(V9,Masterf!$C$1:$CD$9,2,FALSE)) -> 180 | AC9: =IF(E9="H",T9-HLOOKUP(V9,Masterh!$C$1:$CX$9,3,FALSE),T9-HLOOKUP(V9,Masterf!$C$1:$CD$9,3,FALSE)) -> 70 | AD9: =IF(E9="H",T9-HLOOKUP(V9,Masterh!$C$1:$CX$9,4,FALSE),T9-HLOOKUP(V9,Masterf!$C$1:$CD$9,4,FALSE)) -> 48 | AE9: =IF(E9="H",T9-HLOOKUP(V9,Masterh!$C$1:$CX$9,5,FALSE),T9-HLOOKUP(V9,Masterf!$C$1:$CD$9,5,FALSE)) -> 36 | AF9: =IF(E9="H",T9-HLOOKUP(V9,Masterh!$C$1:$CX$9,6,FALSE),T9-HLOOKUP(V9,Masterf!$C$1:$CD$9,6,FALSE)) -> 19 | AG9: =IF(E9="H",T9-HLOOKUP(V9,Masterh!$C$1:$CX$9,7,FALSE),T9-HLOOKUP(V9,Masterf!$C$1:$CD$9,7,FALSE)) -> -820 | AH9: =IF(E9="H",T9-HLOOKUP(V9,Masterh!$C$1:$CX$9,8,FALSE),T9-HLOOKUP(V9,Masterf!$C$1:$CD$9,8,FALSE)) -> -820 | AI9: =IF(E9="H",T9-HLOOKUP(V9,Masterh!$C$1:$CX$9,9,FALSE),T9-HLOOKUP(V9,Masterf!$C$1:$CD$9,9,FALSE)) -> -820 | AJ9: =IF(E9=0," ",IF(AI9>=0,$AI$5,IF(AH9>=0,$AH$5,IF(AG9>=0,$AG$5,IF(AF9>=0,$AF$5,IF(AE9>=0,$AE$5,IF(AD9>=0,$AD$5,IF(AC9>=0,$AC$5,$AB$5)))))))) -> MON + | AL9: =IF(AJ9="","",AJ9) -> MON + | AM9: =IF(E9=0," ",IF(AI9>=0,AI9,IF(AH9>=0,AH9,IF(AG9>=0,AG9,IF(AF9>=0,AF9,IF(AE9>=0,AE9,IF(AD9>=0,AD9,IF(AC9>=0,AC9,AC9)))))))) -> 19 | AN9: =IF(AND(H9<1922),VLOOKUP(K9,Masterh!$F$11:$P$29,11),IF(AND(H9>=1922,H9<1940),VLOOKUP(K9,Masterh!$F$11:$P$29,11),IF(AND(H9>=1940,H9<1945),VLOOKUP(K9,Masterh!$F$11:$P$29,10),IF(AND(H9>=1945,H9<1950),VLOOKUP(K9,Masterh!$F$11:$P$29,9),IF(AND(H9>=1950,H9<1955),VLOOKUP(K9,Masterh!$F$11:$P$29,8),IF(AND(H9>=1955,H9<1960),VLOOKUP(K9,Masterh!$F$11:$P$29,7),IF(AND(H9>=1960,H9<1965),VLOOKUP(K9,Masterh!$F$11:$P$29,6),IF(AND(H9>=1965,H9<1970),VLOOKUP(K9,Masterh!$F$11:$P$29,5),IF(AND(H9>=1970,H9<1975),VLOOKUP(K9,Masterh!$F$11:$P$29,4),IF(AND(H9>=1975,H9<1980),VLOOKUP(K9,Masterh!$F$11:$P$29,3),IF(AND(H9>=1980,H9<1985),VLOOKUP(K9,Masterh!$F$11:$P$29,2),"SENIOR"))))))))))) -> M40 -55 | AO9: =IF(AND(H9<1950),VLOOKUP(K9,Masterf!$F$11:$N$25,9),IF(AND(H9>=1950,H9<1955),VLOOKUP(K9,Masterf!$F$11:$N$25,8),IF(AND(H9>=1955,H9<1960),VLOOKUP(K9,Masterf!$F$11:$N$25,7),IF(AND(H9>=1960,H9<1965),VLOOKUP(K9,Masterf!$F$11:$N$25,6),IF(AND(H9>=1965,H9<1970),VLOOKUP(K9,Masterf!$F$11:$N$25,5),IF(AND(H9>=1970,H9<1975),VLOOKUP(K9,Masterf!$F$11:$N$25,4),IF(AND(H9>=1975,H9<1980),VLOOKUP(K9,Masterf!$F$11:$N$25,3),IF(AND(H9>=1980,H9<1985),VLOOKUP(K9,Masterf!$F$11:$N$25,2),"SENIOR")))))))) -> W40 -55
E10: H | H10: 1975 | K10: 67 | L10: 50 | O10: =IF(E10="","",IF(MAXA(L10:N10)<=0,0,MAXA(L10:N10))) -> 50 | P10: 80 | S10: =IF(E10="","",IF(MAXA(P10:R10)<=0,0,MAXA(P10:R10))) -> 80 | T10: =IF(E10="","",IF(OR(O10=0,S10=0),0,O10+S10)) -> 130 | U10: =+CONCATENATE(AL10," ",AM10) -> REG -10 | V10: =IF(E10=0," ",IF(E10="H",AN10,AO10)) -> M40 -67 | W10: =IF(E10=" "," ",IF(E10="H",10^(0.75194503*LOG(K10/175.508)^2)*T10,IF(E10="F",10^(0.783497476* LOG(K10/153.655)^2)*T10,""))) -> 175.98103 | X10: =IF(E10="","",W10*VLOOKUP(2019-H10,Masterh!C$17:D$72,2,FALSE)) -> 209.24145 | AB10: =IF(E10="H",T10-HLOOKUP(V10,Masterh!$C$1:$CX$9,2,FALSE),T10-HLOOKUP(V10,Masterf!$C$1:$CD$9,2,FALSE)) -> 130 | AC10: =IF(E10="H",T10-HLOOKUP(V10,Masterh!$C$1:$CX$9,3,FALSE),T10-HLOOKUP(V10,Masterf!$C$1:$CD$9,3,FALSE)) -> -10 | AD10: =IF(E10="H",T10-HLOOKUP(V10,Masterh!$C$1:$CX$9,4,FALSE),T10-HLOOKUP(V10,Masterf!$C$1:$CD$9,4,FALSE)) -> -30 | AE10: =IF(E10="H",T10-HLOOKUP(V10,Masterh!$C$1:$CX$9,5,FALSE),T10-HLOOKUP(V10,Masterf!$C$1:$CD$9,5,FALSE)) -> -36 | AF10: =IF(E10="H",T10-HLOOKUP(V10,Masterh!$C$1:$CX$9,6,FALSE),T10-HLOOKUP(V10,Masterf!$C$1:$CD$9,6,FALSE)) -> -54 | AG10: =IF(E10="H",T10-HLOOKUP(V10,Masterh!$C$1:$CX$9,7,FALSE),T10-HLOOKUP(V10,Masterf!$C$1:$CD$9,7,FALSE)) -> -870 | AH10: =IF(E10="H",T10-HLOOKUP(V10,Masterh!$C$1:$CX$9,8,FALSE),T10-HLOOKUP(V10,Masterf!$C$1:$CD$9,8,FALSE)) -> -870 | AI10: =IF(E10="H",T10-HLOOKUP(V10,Masterh!$C$1:$CX$9,9,FALSE),T10-HLOOKUP(V10,Masterf!$C$1:$CD$9,9,FALSE)) -> -870 | AJ10: =IF(E10=0," ",IF(AI10>=0,$AI$5,IF(AH10>=0,$AH$5,IF(AG10>=0,$AG$5,IF(AF10>=0,$AF$5,IF(AE10>=0,$AE$5,IF(AD10>=0,$AD$5,IF(AC10>=0,$AC$5,$AB$5)))))))) -> REG | AL10: =IF(AJ10="","",AJ10) -> REG | AM10: =IF(E10=0," ",IF(AI10>=0,AI10,IF(AH10>=0,AH10,IF(AG10>=0,AG10,IF(AF10>=0,AF10,IF(AE10>=0,AE10,IF(AD10>=0,AD10,IF(AC10>=0,AC10,AC10)))))))) -> -10 | AN10: =IF(AND(H10<1922),VLOOKUP(K10,Masterh!$F$11:$P$29,11),IF(AND(H10>=1922,H10<1940),VLOOKUP(K10,Masterh!$F$11:$P$29,11),IF(AND(H10>=1940,H10<1945),VLOOKUP(K10,Masterh!$F$11:$P$29,10),IF(AND(H10>=1945,H10<1950),VLOOKUP(K10,Masterh!$F$11:$P$29,9),IF(AND(H10>=1950,H10<1955),VLOOKUP(K10,Masterh!$F$11:$P$29,8),IF(AND(H10>=1955,H10<1960),VLOOKUP(K10,Masterh!$F$11:$P$29,7),IF(AND(H10>=1960,H10<1965),VLOOKUP(K10,Masterh!$F$11:$P$29,6),IF(AND(H10>=1965,H10<1970),VLOOKUP(K10,Masterh!$F$11:$P$29,5),IF(AND(H10>=1970,H10<1975),VLOOKUP(K10,Masterh!$F$11:$P$29,4),IF(AND(H10>=1975,H10<1980),VLOOKUP(K10,Masterh!$F$11:$P$29,3),IF(AND(H10>=1980,H10<1985),VLOOKUP(K10,Masterh!$F$11:$P$29,2),"SENIOR"))))))))))) -> M40 -67 | AO10: =IF(AND(H10<1950),VLOOKUP(K10,Masterf!$F$11:$N$25,9),IF(AND(H10>=1950,H10<1955),VLOOKUP(K10,Masterf!$F$11:$N$25,8),IF(AND(H10>=1955,H10<1960),VLOOKUP(K10,Masterf!$F$11:$N$25,7),IF(AND(H10>=1960,H10<1965),VLOOKUP(K10,Masterf!$F$11:$N$25,6),IF(AND(H10>=1965,H10<1970),VLOOKUP(K10,Masterf!$F$11:$N$25,5),IF(AND(H10>=1970,H10<1975),VLOOKUP(K10,Masterf!$F$11:$N$25,4),IF(AND(H10>=1975,H10<1980),VLOOKUP(K10,Masterf!$F$11:$N$25,3),IF(AND(H10>=1980,H10<1985),VLOOKUP(K10,Masterf!$F$11:$N$25,2),"SENIOR")))))))) -> W40 -71
E11: H | H11: 1974 | K11: 75 | L11: 100 | O11: =IF(E11="","",IF(MAXA(L11:N11)<=0,0,MAXA(L11:N11))) -> 100 | P11: 130 | S11: =IF(E11="","",IF(MAXA(P11:R11)<=0,0,MAXA(P11:R11))) -> 130 | T11: =IF(E11="","",IF(OR(O11=0,S11=0),0,O11+S11)) -> 230 | U11: =+CONCATENATE(AL11," ",AM11) -> MON + 40 | V11: =IF(E11=0," ",IF(E11="H",AN11,AO11)) -> M45 -81 | W11: =IF(E11=" "," ",IF(E11="H",10^(0.75194503*LOG(K11/175.508)^2)*T11,IF(E11="F",10^(0.783497476* LOG(K11/153.655)^2)*T11,""))) -> 291.23545 | X11: =IF(E11="","",W11*VLOOKUP(2019-H11,Masterh!C$17:D$72,2,FALSE)) -> 350.35625 | AB11: =IF(E11="H",T11-HLOOKUP(V11,Masterh!$C$1:$CX$9,2,FALSE),T11-HLOOKUP(V11,Masterf!$C$1:$CD$9,2,FALSE)) -> 230 | AC11: =IF(E11="H",T11-HLOOKUP(V11,Masterh!$C$1:$CX$9,3,FALSE),T11-HLOOKUP(V11,Masterf!$C$1:$CD$9,3,FALSE)) -> 80 | AD11: =IF(E11="H",T11-HLOOKUP(V11,Masterh!$C$1:$CX$9,4,FALSE),T11-HLOOKUP(V11,Masterf!$C$1:$CD$9,4,FALSE)) -> 60 | AE11: =IF(E11="H",T11-HLOOKUP(V11,Masterh!$C$1:$CX$9,5,FALSE),T11-HLOOKUP(V11,Masterf!$C$1:$CD$9,5,FALSE)) -> 55 | AF11: =IF(E11="H",T11-HLOOKUP(V11,Masterh!$C$1:$CX$9,6,FALSE),T11-HLOOKUP(V11,Masterf!$C$1:$CD$9,6,FALSE)) -> 40 | AG11: =IF(E11="H",T11-HLOOKUP(V11,Masterh!$C$1:$CX$9,7,FALSE),T11-HLOOKUP(V11,Masterf!$C$1:$CD$9,7,FALSE)) -> -770 | AH11: =IF(E11="H",T11-HLOOKUP(V11,Masterh!$C$1:$CX$9,8,FALSE),T11-HLOOKUP(V11,Masterf!$C$1:$CD$9,8,FALSE)) -> -770 | AI11: =IF(E11="H",T11-HLOOKUP(V11,Masterh!$C$1:$CX$9,9,FALSE),T11-HLOOKUP(V11,Masterf!$C$1:$CD$9,9,FALSE)) -> -770 | AJ11: =IF(E11=0," ",IF(AI11>=0,$AI$5,IF(AH11>=0,$AH$5,IF(AG11>=0,$AG$5,IF(AF11>=0,$AF$5,IF(AE11>=0,$AE$5,IF(AD11>=0,$AD$5,IF(AC11>=0,$AC$5,$AB$5)))))))) -> MON + | AL11: =IF(AJ11="","",AJ11) -> MON + | AM11: =IF(E11=0," ",IF(AI11>=0,AI11,IF(AH11>=0,AH11,IF(AG11>=0,AG11,IF(AF11>=0,AF11,IF(AE11>=0,AE11,IF(AD11>=0,AD11,IF(AC11>=0,AC11,AC11)))))))) -> 40 | AN11: =IF(AND(H11<1922),VLOOKUP(K11,Masterh!$F$11:$P$29,11),IF(AND(H11>=1922,H11<1940),VLOOKUP(K11,Masterh!$F$11:$P$29,11),IF(AND(H11>=1940,H11<1945),VLOOKUP(K11,Masterh!$F$11:$P$29,10),IF(AND(H11>=1945,H11<1950),VLOOKUP(K11,Masterh!$F$11:$P$29,9),IF(AND(H11>=1950,H11<1955),VLOOKUP(K11,Masterh!$F$11:$P$29,8),IF(AND(H11>=1955,H11<1960),VLOOKUP(K11,Masterh!$F$11:$P$29,7),IF(AND(H11>=1960,H11<1965),VLOOKUP(K11,Masterh!$F$11:$P$29,6),IF(AND(H11>=1965,H11<1970),VLOOKUP(K11,Masterh!$F$11:$P$29,5),IF(AND(H11>=1970,H11<1975),VLOOKUP(K11,Masterh!$F$11:$P$29,4),IF(AND(H11>=1975,H11<1980),VLOOKUP(K11,Masterh!$F$11:$P$29,3),IF(AND(H11>=1980,H11<1985),VLOOKUP(K11,Masterh!$F$11:$P$29,2),"SENIOR"))))))))))) -> M45 -81 | AO11: =IF(AND(H11<1950),VLOOKUP(K11,Masterf!$F$11:$N$25,9),IF(AND(H11>=1950,H11<1955),VLOOKUP(K11,Masterf!$F$11:$N$25,8),IF(AND(H11>=1955,H11<1960),VLOOKUP(K11,Masterf!$F$11:$N$25,7),IF(AND(H11>=1960,H11<1965),VLOOKUP(K11,Masterf!$F$11:$N$25,6),IF(AND(H11>=1965,H11<1970),VLOOKUP(K11,Masterf!$F$11:$N$25,5),IF(AND(H11>=1970,H11<1975),VLOOKUP(K11,Masterf!$F$11:$N$25,4),IF(AND(H11>=1975,H11<1980),VLOOKUP(K11,Masterf!$F$11:$N$25,3),IF(AND(H11>=1980,H11<1985),VLOOKUP(K11,Masterf!$F$11:$N$25,2),"SENIOR")))))))) -> W45 -76
E12: H | H12: 1965 | K12: 75 | O12: =IF(E12="","",IF(MAXA(L12:N12)<=0,0,MAXA(L12:N12))) -> 0 | S12: =IF(E12="","",IF(MAXA(P12:R12)<=0,0,MAXA(P12:R12))) -> 0 | T12: =IF(E12="","",IF(OR(O12=0,S12=0),0,O12+S12)) -> 0 | U12: =+CONCATENATE(AL12," ",AM12) -> REG -135 | V12: =IF(E12=0," ",IF(E12="H",AN12,AO12)) -> M50 -81 | W12: =IF(E12=" "," ",IF(E12="H",10^(0.75194503*LOG(K12/175.508)^2)*T12,IF(E12="F",10^(0.783497476* LOG(K12/153.655)^2)*T12,""))) -> 0 | X12: =IF(E12="","",W12*VLOOKUP(2019-H12,Masterh!C$17:D$72,2,FALSE)) -> 0 | AB12: =IF(E12="H",T12-HLOOKUP(V12,Masterh!$C$1:$CX$9,2,FALSE),T12-HLOOKUP(V12,Masterf!$C$1:$CD$9,2,FALSE)) -> 0 | AC12: =IF(E12="H",T12-HLOOKUP(V12,Masterh!$C$1:$CX$9,3,FALSE),T12-HLOOKUP(V12,Masterf!$C$1:$CD$9,3,FALSE)) -> -135 | AD12: =IF(E12="H",T12-HLOOKUP(V12,Masterh!$C$1:$CX$9,4,FALSE),T12-HLOOKUP(V12,Masterf!$C$1:$CD$9,4,FALSE)) -> -157 | AE12: =IF(E12="H",T12-HLOOKUP(V12,Masterh!$C$1:$CX$9,5,FALSE),T12-HLOOKUP(V12,Masterf!$C$1:$CD$9,5,FALSE)) -> -164 | AF12: =IF(E12="H",T12-HLOOKUP(V12,Masterh!$C$1:$CX$9,6,FALSE),T12-HLOOKUP(V12,Masterf!$C$1:$CD$9,6,FALSE)) -> -175 | AG12: =IF(E12="H",T12-HLOOKUP(V12,Masterh!$C$1:$CX$9,7,FALSE),T12-HLOOKUP(V12,Masterf!$C$1:$CD$9,7,FALSE)) -> -1000 | AH12: =IF(E12="H",T12-HLOOKUP(V12,Masterh!$C$1:$CX$9,8,FALSE),T12-HLOOKUP(V12,Masterf!$C$1:$CD$9,8,FALSE)) -> -1000 | AI12: =IF(E12="H",T12-HLOOKUP(V12,Masterh!$C$1:$CX$9,9,FALSE),T12-HLOOKUP(V12,Masterf!$C$1:$CD$9,9,FALSE)) -> -1000 | AJ12: =IF(E12=0," ",IF(AI12>=0,$AI$5,IF(AH12>=0,$AH$5,IF(AG12>=0,$AG$5,IF(AF12>=0,$AF$5,IF(AE12>=0,$AE$5,IF(AD12>=0,$AD$5,IF(AC12>=0,$AC$5,$AB$5)))))))) -> REG | AL12: =IF(AJ12="","",AJ12) -> REG | AM12: =IF(E12=0," ",IF(AI12>=0,AI12,IF(AH12>=0,AH12,IF(AG12>=0,AG12,IF(AF12>=0,AF12,IF(AE12>=0,AE12,IF(AD12>=0,AD12,IF(AC12>=0,AC12,AC12)))))))) -> -135 | AN12: =IF(AND(H12<1922),VLOOKUP(K12,Masterh!$F$11:$P$29,11),IF(AND(H12>=1922,H12<1940),VLOOKUP(K12,Masterh!$F$11:$P$29,11),IF(AND(H12>=1940,H12<1945),VLOOKUP(K12,Masterh!$F$11:$P$29,10),IF(AND(H12>=1945,H12<1950),VLOOKUP(K12,Masterh!$F$11:$P$29,9),IF(AND(H12>=1950,H12<1955),VLOOKUP(K12,Masterh!$F$11:$P$29,8),IF(AND(H12>=1955,H12<1960),VLOOKUP(K12,Masterh!$F$11:$P$29,7),IF(AND(H12>=1960,H12<1965),VLOOKUP(K12,Masterh!$F$11:$P$29,6),IF(AND(H12>=1965,H12<1970),VLOOKUP(K12,Masterh!$F$11:$P$29,5),IF(AND(H12>=1970,H12<1975),VLOOKUP(K12,Masterh!$F$11:$P$29,4),IF(AND(H12>=1975,H12<1980),VLOOKUP(K12,Masterh!$F$11:$P$29,3),IF(AND(H12>=1980,H12<1985),VLOOKUP(K12,Masterh!$F$11:$P$29,2),"SENIOR"))))))))))) -> M50 -81 | AO12: =IF(AND(H12<1950),VLOOKUP(K12,Masterf!$F$11:$N$25,9),IF(AND(H12>=1950,H12<1955),VLOOKUP(K12,Masterf!$F$11:$N$25,8),IF(AND(H12>=1955,H12<1960),VLOOKUP(K12,Masterf!$F$11:$N$25,7),IF(AND(H12>=1960,H12<1965),VLOOKUP(K12,Masterf!$F$11:$N$25,6),IF(AND(H12>=1965,H12<1970),VLOOKUP(K12,Masterf!$F$11:$N$25,5),IF(AND(H12>=1970,H12<1975),VLOOKUP(K12,Masterf!$F$11:$N$25,4),IF(AND(H12>=1975,H12<1980),VLOOKUP(K12,Masterf!$F$11:$N$25,3),IF(AND(H12>=1980,H12<1985),VLOOKUP(K12,Masterf!$F$11:$N$25,2),"SENIOR")))))))) -> W50 -76
E13: H | H13: 1935 | K13: 75 | O13: =IF(E13="","",IF(MAXA(L13:N13)<=0,0,MAXA(L13:N13))) -> 0 | S13: =IF(E13="","",IF(MAXA(P13:R13)<=0,0,MAXA(P13:R13))) -> 0 | T13: =IF(E13="","",IF(OR(O13=0,S13=0),0,O13+S13)) -> 0 | U13: =+CONCATENATE(AL13," ",AM13) -> REG -52 | V13: =IF(E13=0," ",IF(E13="H",AN13,AO13)) -> M80 -81 | W13: =IF(E13=" "," ",IF(E13="H",10^(0.75194503*LOG(K13/175.508)^2)*T13,IF(E13="F",10^(0.783497476* LOG(K13/153.655)^2)*T13,""))) -> 0 | X13: =IF(E13="","",W13*VLOOKUP(2019-H13,Masterh!C$17:D$72,2,FALSE)) -> 0 | AB13: =IF(E13="H",T13-HLOOKUP(V13,Masterh!$C$1:$CX$9,2,FALSE),T13-HLOOKUP(V13,Masterf!$C$1:$CD$9,2,FALSE)) -> 0 | AC13: =IF(E13="H",T13-HLOOKUP(V13,Masterh!$C$1:$CX$9,3,FALSE),T13-HLOOKUP(V13,Masterf!$C$1:$CD$9,3,FALSE)) -> -52 | AD13: =IF(E13="H",T13-HLOOKUP(V13,Masterh!$C$1:$CX$9,4,FALSE),T13-HLOOKUP(V13,Masterf!$C$1:$CD$9,4,FALSE)) -> -63 | AE13: =IF(E13="H",T13-HLOOKUP(V13,Masterh!$C$1:$CX$9,5,FALSE),T13-HLOOKUP(V13,Masterf!$C$1:$CD$9,5,FALSE)) -> -69 | AF13: =IF(E13="H",T13-HLOOKUP(V13,Masterh!$C$1:$CX$9,6,FALSE),T13-HLOOKUP(V13,Masterf!$C$1:$CD$9,6,FALSE)) -> -76 | AG13: =IF(E13="H",T13-HLOOKUP(V13,Masterh!$C$1:$CX$9,7,FALSE),T13-HLOOKUP(V13,Masterf!$C$1:$CD$9,7,FALSE)) -> -1000 | AH13: =IF(E13="H",T13-HLOOKUP(V13,Masterh!$C$1:$CX$9,8,FALSE),T13-HLOOKUP(V13,Masterf!$C$1:$CD$9,8,FALSE)) -> -1000 | AI13: =IF(E13="H",T13-HLOOKUP(V13,Masterh!$C$1:$CX$9,9,FALSE),T13-HLOOKUP(V13,Masterf!$C$1:$CD$9,9,FALSE)) -> -1000 | AJ13: =IF(E13=0," ",IF(AI13>=0,$AI$5,IF(AH13>=0,$AH$5,IF(AG13>=0,$AG$5,IF(AF13>=0,$AF$5,IF(AE13>=0,$AE$5,IF(AD13>=0,$AD$5,IF(AC13>=0,$AC$5,$AB$5)))))))) -> REG | AL13: =IF(AJ13="","",AJ13) -> REG | AM13: =IF(E13=0," ",IF(AI13>=0,AI13,IF(AH13>=0,AH13,IF(AG13>=0,AG13,IF(AF13>=0,AF13,IF(AE13>=0,AE13,IF(AD13>=0,AD13,IF(AC13>=0,AC13,AC13)))))))) -> -52 | AN13: =IF(AND(H13<1922),VLOOKUP(K13,Masterh!$F$11:$P$29,11),IF(AND(H13>=1922,H13<1940),VLOOKUP(K13,Masterh!$F$11:$P$29,11),IF(AND(H13>=1940,H13<1945),VLOOKUP(K13,Masterh!$F$11:$P$29,10),IF(AND(H13>=1945,H13<1950),VLOOKUP(K13,Masterh!$F$11:$P$29,9),IF(AND(H13>=1950,H13<1955),VLOOKUP(K13,Masterh!$F$11:$P$29,8),IF(AND(H13>=1955,H13<1960),VLOOKUP(K13,Masterh!$F$11:$P$29,7),IF(AND(H13>=1960,H13<1965),VLOOKUP(K13,Masterh!$F$11:$P$29,6),IF(AND(H13>=1965,H13<1970),VLOOKUP(K13,Masterh!$F$11:$P$29,5),IF(AND(H13>=1970,H13<1975),VLOOKUP(K13,Masterh!$F$11:$P$29,4),IF(AND(H13>=1975,H13<1980),VLOOKUP(K13,Masterh!$F$11:$P$29,3),IF(AND(H13>=1980,H13<1985),VLOOKUP(K13,Masterh!$F$11:$P$29,2),"SENIOR"))))))))))) -> M80 -81 | AO13: =IF(AND(H13<1950),VLOOKUP(K13,Masterf!$F$11:$N$25,9),IF(AND(H13>=1950,H13<1955),VLOOKUP(K13,Masterf!$F$11:$N$25,8),IF(AND(H13>=1955,H13<1960),VLOOKUP(K13,Masterf!$F$11:$N$25,7),IF(AND(H13>=1960,H13<1965),VLOOKUP(K13,Masterf!$F$11:$N$25,6),IF(AND(H13>=1965,H13<1970),VLOOKUP(K13,Masterf!$F$11:$N$25,5),IF(AND(H13>=1970,H13<1975),VLOOKUP(K13,Masterf!$F$11:$N$25,4),IF(AND(H13>=1975,H13<1980),VLOOKUP(K13,Masterf!$F$11:$N$25,3),IF(AND(H13>=1980,H13<1985),VLOOKUP(K13,Masterf!$F$11:$N$25,2),"SENIOR")))))))) -> W70 -76
E14: H | H14: 1950 | K14: 75 | O14: =IF(E14="","",IF(MAXA(L14:N14)<=0,0,MAXA(L14:N14))) -> 0 | S14: =IF(E14="","",IF(MAXA(P14:R14)<=0,0,MAXA(P14:R14))) -> 0 | T14: =IF(E14="","",IF(OR(O14=0,S14=0),0,O14+S14)) -> 0 | U14: =+CONCATENATE(AL14," ",AM14) -> REG -90 | V14: =IF(E14=0," ",IF(E14="H",AN14,AO14)) -> M65 -81 | W14: =IF(E14=" "," ",IF(E14="H",10^(0.75194503*LOG(K14/175.508)^2)*T14,IF(E14="F",10^(0.783497476* LOG(K14/153.655)^2)*T14,""))) -> 0 | X14: =IF(E14="","",W14*VLOOKUP(2019-H14,Masterh!C$17:D$72,2,FALSE)) -> 0 | AB14: =IF(E14="H",T14-HLOOKUP(V14,Masterh!$C$1:$CX$9,2,FALSE),T14-HLOOKUP(V14,Masterf!$C$1:$CD$9,2,FALSE)) -> 0 | AC14: =IF(E14="H",T14-HLOOKUP(V14,Masterh!$C$1:$CX$9,3,FALSE),T14-HLOOKUP(V14,Masterf!$C$1:$CD$9,3,FALSE)) -> -90 | AD14: =IF(E14="H",T14-HLOOKUP(V14,Masterh!$C$1:$CX$9,4,FALSE),T14-HLOOKUP(V14,Masterf!$C$1:$CD$9,4,FALSE)) -> -107 | AE14: =IF(E14="H",T14-HLOOKUP(V14,Masterh!$C$1:$CX$9,5,FALSE),T14-HLOOKUP(V14,Masterf!$C$1:$CD$9,5,FALSE)) -> -113 | AF14: =IF(E14="H",T14-HLOOKUP(V14,Masterh!$C$1:$CX$9,6,FALSE),T14-HLOOKUP(V14,Masterf!$C$1:$CD$9,6,FALSE)) -> -125 | AG14: =IF(E14="H",T14-HLOOKUP(V14,Masterh!$C$1:$CX$9,7,FALSE),T14-HLOOKUP(V14,Masterf!$C$1:$CD$9,7,FALSE)) -> -1000 | AH14: =IF(E14="H",T14-HLOOKUP(V14,Masterh!$C$1:$CX$9,8,FALSE),T14-HLOOKUP(V14,Masterf!$C$1:$CD$9,8,FALSE)) -> -1000 | AI14: =IF(E14="H",T14-HLOOKUP(V14,Masterh!$C$1:$CX$9,9,FALSE),T14-HLOOKUP(V14,Masterf!$C$1:$CD$9,9,FALSE)) -> -1000 | AJ14: =IF(E14=0," ",IF(AI14>=0,$AI$5,IF(AH14>=0,$AH$5,IF(AG14>=0,$AG$5,IF(AF14>=0,$AF$5,IF(AE14>=0,$AE$5,IF(AD14>=0,$AD$5,IF(AC14>=0,$AC$5,$AB$5)))))))) -> REG | AL14: =IF(AJ14="","",AJ14) -> REG | AM14: =IF(E14=0," ",IF(AI14>=0,AI14,IF(AH14>=0,AH14,IF(AG14>=0,AG14,IF(AF14>=0,AF14,IF(AE14>=0,AE14,IF(AD14>=0,AD14,IF(AC14>=0,AC14,AC14)))))))) -> -90 | AN14: =IF(AND(H14<1922),VLOOKUP(K14,Masterh!$F$11:$P$29,11),IF(AND(H14>=1922,H14<1940),VLOOKUP(K14,Masterh!$F$11:$P$29,11),IF(AND(H14>=1940,H14<1945),VLOOKUP(K14,Masterh!$F$11:$P$29,10),IF(AND(H14>=1945,H14<1950),VLOOKUP(K14,Masterh!$F$11:$P$29,9),IF(AND(H14>=1950,H14<1955),VLOOKUP(K14,Masterh!$F$11:$P$29,8),IF(AND(H14>=1955,H14<1960),VLOOKUP(K14,Masterh!$F$11:$P$29,7),IF(AND(H14>=1960,H14<1965),VLOOKUP(K14,Masterh!$F$11:$P$29,6),IF(AND(H14>=1965,H14<1970),VLOOKUP(K14,Masterh!$F$11:$P$29,5),IF(AND(H14>=1970,H14<1975),VLOOKUP(K14,Masterh!$F$11:$P$29,4),IF(AND(H14>=1975,H14<1980),VLOOKUP(K14,Masterh!$F$11:$P$29,3),IF(AND(H14>=1980,H14<1985),VLOOKUP(K14,Masterh!$F$11:$P$29,2),"SENIOR"))))))))))) -> M65 -81 | AO14: =IF(AND(H14<1950),VLOOKUP(K14,Masterf!$F$11:$N$25,9),IF(AND(H14>=1950,H14<1955),VLOOKUP(K14,Masterf!$F$11:$N$25,8),IF(AND(H14>=1955,H14<1960),VLOOKUP(K14,Masterf!$F$11:$N$25,7),IF(AND(H14>=1960,H14<1965),VLOOKUP(K14,Masterf!$F$11:$N$25,6),IF(AND(H14>=1965,H14<1970),VLOOKUP(K14,Masterf!$F$11:$N$25,5),IF(AND(H14>=1970,H14<1975),VLOOKUP(K14,Masterf!$F$11:$N$25,4),IF(AND(H14>=1975,H14<1980),VLOOKUP(K14,Masterf!$F$11:$N$25,3),IF(AND(H14>=1980,H14<1985),VLOOKUP(K14,Masterf!$F$11:$N$25,2),"SENIOR")))))))) -> W65 -76
E15: H | H15: 1949 | K15: 89 | O15: =IF(E15="","",IF(MAXA(L15:N15)<=0,0,MAXA(L15:N15))) -> 0 | S15: =IF(E15="","",IF(MAXA(P15:R15)<=0,0,MAXA(P15:R15))) -> 0 | T15: =IF(E15="","",IF(OR(O15=0,S15=0),0,O15+S15)) -> 0 | U15: =+CONCATENATE(AL15," ",AM15) -> REG -72 | V15: =IF(E15=0," ",IF(E15="H",AN15,AO15)) -> M70 -89 | W15: =IF(E15=" "," ",IF(E15="H",10^(0.75194503*LOG(K15/175.508)^2)*T15,IF(E15="F",10^(0.783497476* LOG(K15/153.655)^2)*T15,""))) -> 0 | X15: =IF(E15="","",W15*VLOOKUP(2019-H15,Masterh!C$17:D$72,2,FALSE)) -> 0 | AB15: =IF(E15="H",T15-HLOOKUP(V15,Masterh!$C$1:$CX$9,2,FALSE),T15-HLOOKUP(V15,Masterf!$C$1:$CD$9,2,FALSE)) -> 0 | AC15: =IF(E15="H",T15-HLOOKUP(V15,Masterh!$C$1:$CX$9,3,FALSE),T15-HLOOKUP(V15,Masterf!$C$1:$CD$9,3,FALSE)) -> -72 | AD15: =IF(E15="H",T15-HLOOKUP(V15,Masterh!$C$1:$CX$9,4,FALSE),T15-HLOOKUP(V15,Masterf!$C$1:$CD$9,4,FALSE)) -> -95 | AE15: =IF(E15="H",T15-HLOOKUP(V15,Masterh!$C$1:$CX$9,5,FALSE),T15-HLOOKUP(V15,Masterf!$C$1:$CD$9,5,FALSE)) -> -101 | AF15: =IF(E15="H",T15-HLOOKUP(V15,Masterh!$C$1:$CX$9,6,FALSE),T15-HLOOKUP(V15,Masterf!$C$1:$CD$9,6,FALSE)) -> -114 | AG15: =IF(E15="H",T15-HLOOKUP(V15,Masterh!$C$1:$CX$9,7,FALSE),T15-HLOOKUP(V15,Masterf!$C$1:$CD$9,7,FALSE)) -> -1000 | AH15: =IF(E15="H",T15-HLOOKUP(V15,Masterh!$C$1:$CX$9,8,FALSE),T15-HLOOKUP(V15,Masterf!$C$1:$CD$9,8,FALSE)) -> -1000 | AI15: =IF(E15="H",T15-HLOOKUP(V15,Masterh!$C$1:$CX$9,9,FALSE),T15-HLOOKUP(V15,Masterf!$C$1:$CD$9,9,FALSE)) -> -1000 | AJ15: =IF(E15=0," ",IF(AI15>=0,$AI$5,IF(AH15>=0,$AH$5,IF(AG15>=0,$AG$5,IF(AF15>=0,$AF$5,IF(AE15>=0,$AE$5,IF(AD15>=0,$AD$5,IF(AC15>=0,$AC$5,$AB$5)))))))) -> REG | AL15: =IF(AJ15="","",AJ15) -> REG | AM15: =IF(E15=0," ",IF(AI15>=0,AI15,IF(AH15>=0,AH15,IF(AG15>=0,AG15,IF(AF15>=0,AF15,IF(AE15>=0,AE15,IF(AD15>=0,AD15,IF(AC15>=0,AC15,AC15)))))))) -> -72 | AN15: =IF(AND(H15<1922),VLOOKUP(K15,Masterh!$F$11:$P$29,11),IF(AND(H15>=1922,H15<1940),VLOOKUP(K15,Masterh!$F$11:$P$29,11),IF(AND(H15>=1940,H15<1945),VLOOKUP(K15,Masterh!$F$11:$P$29,10),IF(AND(H15>=1945,H15<1950),VLOOKUP(K15,Masterh!$F$11:$P$29,9),IF(AND(H15>=1950,H15<1955),VLOOKUP(K15,Masterh!$F$11:$P$29,8),IF(AND(H15>=1955,H15<1960),VLOOKUP(K15,Masterh!$F$11:$P$29,7),IF(AND(H15>=1960,H15<1965),VLOOKUP(K15,Masterh!$F$11:$P$29,6),IF(AND(H15>=1965,H15<1970),VLOOKUP(K15,Masterh!$F$11:$P$29,5),IF(AND(H15>=1970,H15<1975),VLOOKUP(K15,Masterh!$F$11:$P$29,4),IF(AND(H15>=1975,H15<1980),VLOOKUP(K15,Masterh!$F$11:$P$29,3),IF(AND(H15>=1980,H15<1985),VLOOKUP(K15,Masterh!$F$11:$P$29,2),"SENIOR"))))))))))) -> M70 -89 | AO15: =IF(AND(H15<1950),VLOOKUP(K15,Masterf!$F$11:$N$25,9),IF(AND(H15>=1950,H15<1955),VLOOKUP(K15,Masterf!$F$11:$N$25,8),IF(AND(H15>=1955,H15<1960),VLOOKUP(K15,Masterf!$F$11:$N$25,7),IF(AND(H15>=1960,H15<1965),VLOOKUP(K15,Masterf!$F$11:$N$25,6),IF(AND(H15>=1965,H15<1970),VLOOKUP(K15,Masterf!$F$11:$N$25,5),IF(AND(H15>=1970,H15<1975),VLOOKUP(K15,Masterf!$F$11:$N$25,4),IF(AND(H15>=1975,H15<1980),VLOOKUP(K15,Masterf!$F$11:$N$25,3),IF(AND(H15>=1980,H15<1985),VLOOKUP(K15,Masterf!$F$11:$N$25,2),"SENIOR")))))))) -> W70 >87
E16: H | H16: 1945 | K16: 75 | O16: =IF(E16="","",IF(MAXA(L16:N16)<=0,0,MAXA(L16:N16))) -> 0 | S16: =IF(E16="","",IF(MAXA(P16:R16)<=0,0,MAXA(P16:R16))) -> 0 | T16: =IF(E16="","",IF(OR(O16=0,S16=0),0,O16+S16)) -> 0 | U16: =+CONCATENATE(AL16," ",AM16) -> REG -70 | V16: =IF(E16=0," ",IF(E16="H",AN16,AO16)) -> M70 -81 | W16: =IF(E16=" "," ",IF(E16="H",10^(0.75194503*LOG(K16/175.508)^2)*T16,IF(E16="F",10^(0.783497476* LOG(K16/153.655)^2)*T16,""))) -> 0 | X16: =IF(E16="","",W16*VLOOKUP(2019-H16,Masterh!C$17:D$72,2,FALSE)) -> 0 | AB16: =IF(E16="H",T16-HLOOKUP(V16,Masterh!$C$1:$CX$9,2,FALSE),T16-HLOOKUP(V16,Masterf!$C$1:$CD$9,2,FALSE)) -> 0 | AC16: =IF(E16="H",T16-HLOOKUP(V16,Masterh!$C$1:$CX$9,3,FALSE),T16-HLOOKUP(V16,Masterf!$C$1:$CD$9,3,FALSE)) -> -70 | AD16: =IF(E16="H",T16-HLOOKUP(V16,Masterh!$C$1:$CX$9,4,FALSE),T16-HLOOKUP(V16,Masterf!$C$1:$CD$9,4,FALSE)) -> -90 | AE16: =IF(E16="H",T16-HLOOKUP(V16,Masterh!$C$1:$CX$9,5,FALSE),T16-HLOOKUP(V16,Masterf!$C$1:$CD$9,5,FALSE)) -> -96 | AF16: =IF(E16="H",T16-HLOOKUP(V16,Masterh!$C$1:$CX$9,6,FALSE),T16-HLOOKUP(V16,Masterf!$C$1:$CD$9,6,FALSE)) -> -109 | AG16: =IF(E16="H",T16-HLOOKUP(V16,Masterh!$C$1:$CX$9,7,FALSE),T16-HLOOKUP(V16,Masterf!$C$1:$CD$9,7,FALSE)) -> -1000 | AH16: =IF(E16="H",T16-HLOOKUP(V16,Masterh!$C$1:$CX$9,8,FALSE),T16-HLOOKUP(V16,Masterf!$C$1:$CD$9,8,FALSE)) -> -1000 | AI16: =IF(E16="H",T16-HLOOKUP(V16,Masterh!$C$1:$CX$9,9,FALSE),T16-HLOOKUP(V16,Masterf!$C$1:$CD$9,9,FALSE)) -> -1000 | AJ16: =IF(E16=0," ",IF(AI16>=0,$AI$5,IF(AH16>=0,$AH$5,IF(AG16>=0,$AG$5,IF(AF16>=0,$AF$5,IF(AE16>=0,$AE$5,IF(AD16>=0,$AD$5,IF(AC16>=0,$AC$5,$AB$5)))))))) -> REG | AL16: =IF(AJ16="","",AJ16) -> REG | AM16: =IF(E16=0," ",IF(AI16>=0,AI16,IF(AH16>=0,AH16,IF(AG16>=0,AG16,IF(AF16>=0,AF16,IF(AE16>=0,AE16,IF(AD16>=0,AD16,IF(AC16>=0,AC16,AC16)))))))) -> -70 | AN16: =IF(AND(H16<1922),VLOOKUP(K16,Masterh!$F$11:$P$29,11),IF(AND(H16>=1922,H16<1940),VLOOKUP(K16,Masterh!$F$11:$P$29,11),IF(AND(H16>=1940,H16<1945),VLOOKUP(K16,Masterh!$F$11:$P$29,10),IF(AND(H16>=1945,H16<1950),VLOOKUP(K16,Masterh!$F$11:$P$29,9),IF(AND(H16>=1950,H16<1955),VLOOKUP(K16,Masterh!$F$11:$P$29,8),IF(AND(H16>=1955,H16<1960),VLOOKUP(K16,Masterh!$F$11:$P$29,7),IF(AND(H16>=1960,H16<1965),VLOOKUP(K16,Masterh!$F$11:$P$29,6),IF(AND(H16>=1965,H16<1970),VLOOKUP(K16,Masterh!$F$11:$P$29,5),IF(AND(H16>=1970,H16<1975),VLOOKUP(K16,Masterh!$F$11:$P$29,4),IF(AND(H16>=1975,H16<1980),VLOOKUP(K16,Masterh!$F$11:$P$29,3),IF(AND(H16>=1980,H16<1985),VLOOKUP(K16,Masterh!$F$11:$P$29,2),"SENIOR"))))))))))) -> M70 -81 | AO16: =IF(AND(H16<1950),VLOOKUP(K16,Masterf!$F$11:$N$25,9),IF(AND(H16>=1950,H16<1955),VLOOKUP(K16,Masterf!$F$11:$N$25,8),IF(AND(H16>=1955,H16<1960),VLOOKUP(K16,Masterf!$F$11:$N$25,7),IF(AND(H16>=1960,H16<1965),VLOOKUP(K16,Masterf!$F$11:$N$25,6),IF(AND(H16>=1965,H16<1970),VLOOKUP(K16,Masterf!$F$11:$N$25,5),IF(AND(H16>=1970,H16<1975),VLOOKUP(K16,Masterf!$F$11:$N$25,4),IF(AND(H16>=1975,H16<1980),VLOOKUP(K16,Masterf!$F$11:$N$25,3),IF(AND(H16>=1980,H16<1985),VLOOKUP(K16,Masterf!$F$11:$N$25,2),"SENIOR")))))))) -> W70 -76
E17: H | H17: 1944 | K17: 75 | O17: =IF(E17="","",IF(MAXA(L17:N17)<=0,0,MAXA(L17:N17))) -> 0 | S17: =IF(E17="","",IF(MAXA(P17:R17)<=0,0,MAXA(P17:R17))) -> 0 | T17: =IF(E17="","",IF(OR(O17=0,S17=0),0,O17+S17)) -> 0 | U17: =+CONCATENATE(AL17," ",AM17) -> REG -60 | V17: =IF(E17=0," ",IF(E17="H",AN17,AO17)) -> M75 -81 | W17: =IF(E17=" "," ",IF(E17="H",10^(0.75194503*LOG(K17/175.508)^2)*T17,IF(E17="F",10^(0.783497476* LOG(K17/153.655)^2)*T17,""))) -> 0 | X17: =IF(E17="","",W17*VLOOKUP(2019-H17,Masterh!C$17:D$72,2,FALSE)) -> 0 | AB17: =IF(E17="H",T17-HLOOKUP(V17,Masterh!$C$1:$CX$9,2,FALSE),T17-HLOOKUP(V17,Masterf!$C$1:$CD$9,2,FALSE)) -> 0 | AC17: =IF(E17="H",T17-HLOOKUP(V17,Masterh!$C$1:$CX$9,3,FALSE),T17-HLOOKUP(V17,Masterf!$C$1:$CD$9,3,FALSE)) -> -60 | AD17: =IF(E17="H",T17-HLOOKUP(V17,Masterh!$C$1:$CX$9,4,FALSE),T17-HLOOKUP(V17,Masterf!$C$1:$CD$9,4,FALSE)) -> -77 | AE17: =IF(E17="H",T17-HLOOKUP(V17,Masterh!$C$1:$CX$9,5,FALSE),T17-HLOOKUP(V17,Masterf!$C$1:$CD$9,5,FALSE)) -> -83 | AF17: =IF(E17="H",T17-HLOOKUP(V17,Masterh!$C$1:$CX$9,6,FALSE),T17-HLOOKUP(V17,Masterf!$C$1:$CD$9,6,FALSE)) -> -93 | AG17: =IF(E17="H",T17-HLOOKUP(V17,Masterh!$C$1:$CX$9,7,FALSE),T17-HLOOKUP(V17,Masterf!$C$1:$CD$9,7,FALSE)) -> -1000 | AH17: =IF(E17="H",T17-HLOOKUP(V17,Masterh!$C$1:$CX$9,8,FALSE),T17-HLOOKUP(V17,Masterf!$C$1:$CD$9,8,FALSE)) -> -1000 | AI17: =IF(E17="H",T17-HLOOKUP(V17,Masterh!$C$1:$CX$9,9,FALSE),T17-HLOOKUP(V17,Masterf!$C$1:$CD$9,9,FALSE)) -> -1000 | AJ17: =IF(E17=0," ",IF(AI17>=0,$AI$5,IF(AH17>=0,$AH$5,IF(AG17>=0,$AG$5,IF(AF17>=0,$AF$5,IF(AE17>=0,$AE$5,IF(AD17>=0,$AD$5,IF(AC17>=0,$AC$5,$AB$5)))))))) -> REG | AL17: =IF(AJ17="","",AJ17) -> REG | AM17: =IF(E17=0," ",IF(AI17>=0,AI17,IF(AH17>=0,AH17,IF(AG17>=0,AG17,IF(AF17>=0,AF17,IF(AE17>=0,AE17,IF(AD17>=0,AD17,IF(AC17>=0,AC17,AC17)))))))) -> -60 | AN17: =IF(AND(H17<1922),VLOOKUP(K17,Masterh!$F$11:$P$29,11),IF(AND(H17>=1922,H17<1940),VLOOKUP(K17,Masterh!$F$11:$P$29,11),IF(AND(H17>=1940,H17<1945),VLOOKUP(K17,Masterh!$F$11:$P$29,10),IF(AND(H17>=1945,H17<1950),VLOOKUP(K17,Masterh!$F$11:$P$29,9),IF(AND(H17>=1950,H17<1955),VLOOKUP(K17,Masterh!$F$11:$P$29,8),IF(AND(H17>=1955,H17<1960),VLOOKUP(K17,Masterh!$F$11:$P$29,7),IF(AND(H17>=1960,H17<1965),VLOOKUP(K17,Masterh!$F$11:$P$29,6),IF(AND(H17>=1965,H17<1970),VLOOKUP(K17,Masterh!$F$11:$P$29,5),IF(AND(H17>=1970,H17<1975),VLOOKUP(K17,Masterh!$F$11:$P$29,4),IF(AND(H17>=1975,H17<1980),VLOOKUP(K17,Masterh!$F$11:$P$29,3),IF(AND(H17>=1980,H17<1985),VLOOKUP(K17,Masterh!$F$11:$P$29,2),"SENIOR"))))))))))) -> M75 -81 | AO17: =IF(AND(H17<1950),VLOOKUP(K17,Masterf!$F$11:$N$25,9),IF(AND(H17>=1950,H17<1955),VLOOKUP(K17,Masterf!$F$11:$N$25,8),IF(AND(H17>=1955,H17<1960),VLOOKUP(K17,Masterf!$F$11:$N$25,7),IF(AND(H17>=1960,H17<1965),VLOOKUP(K17,Masterf!$F$11:$N$25,6),IF(AND(H17>=1965,H17<1970),VLOOKUP(K17,Masterf!$F$11:$N$25,5),IF(AND(H17>=1970,H17<1975),VLOOKUP(K17,Masterf!$F$11:$N$25,4),IF(AND(H17>=1975,H17<1980),VLOOKUP(K17,Masterf!$F$11:$N$25,3),IF(AND(H17>=1980,H17<1985),VLOOKUP(K17,Masterf!$F$11:$N$25,2),"SENIOR")))))))) -> W70 -76
E18: H | H18: 1954 | K18: 75 | O18: =IF(E18="","",IF(MAXA(L18:N18)<=0,0,MAXA(L18:N18))) -> 0 | S18: =IF(E18="","",IF(MAXA(P18:R18)<=0,0,MAXA(P18:R18))) -> 0 | T18: =IF(E18="","",IF(OR(O18=0,S18=0),0,O18+S18)) -> 0 | U18: =+CONCATENATE(AL18," ",AM18) -> REG -90 | V18: =IF(E18=0," ",IF(E18="H",AN18,AO18)) -> M65 -81 | W18: =IF(E18=" "," ",IF(E18="H",10^(0.75194503*LOG(K18/175.508)^2)*T18,IF(E18="F",10^(0.783497476* LOG(K18/153.655)^2)*T18,""))) -> 0 | X18: =IF(E18="","",W18*VLOOKUP(2019-H18,Masterh!C$17:D$72,2,FALSE)) -> 0 | AB18: =IF(E18="H",T18-HLOOKUP(V18,Masterh!$C$1:$CX$9,2,FALSE),T18-HLOOKUP(V18,Masterf!$C$1:$CD$9,2,FALSE)) -> 0 | AC18: =IF(E18="H",T18-HLOOKUP(V18,Masterh!$C$1:$CX$9,3,FALSE),T18-HLOOKUP(V18,Masterf!$C$1:$CD$9,3,FALSE)) -> -90 | AD18: =IF(E18="H",T18-HLOOKUP(V18,Masterh!$C$1:$CX$9,4,FALSE),T18-HLOOKUP(V18,Masterf!$C$1:$CD$9,4,FALSE)) -> -107 | AE18: =IF(E18="H",T18-HLOOKUP(V18,Masterh!$C$1:$CX$9,5,FALSE),T18-HLOOKUP(V18,Masterf!$C$1:$CD$9,5,FALSE)) -> -113 | AF18: =IF(E18="H",T18-HLOOKUP(V18,Masterh!$C$1:$CX$9,6,FALSE),T18-HLOOKUP(V18,Masterf!$C$1:$CD$9,6,FALSE)) -> -125 | AG18: =IF(E18="H",T18-HLOOKUP(V18,Masterh!$C$1:$CX$9,7,FALSE),T18-HLOOKUP(V18,Masterf!$C$1:$CD$9,7,FALSE)) -> -1000 | AH18: =IF(E18="H",T18-HLOOKUP(V18,Masterh!$C$1:$CX$9,8,FALSE),T18-HLOOKUP(V18,Masterf!$C$1:$CD$9,8,FALSE)) -> -1000 | AI18: =IF(E18="H",T18-HLOOKUP(V18,Masterh!$C$1:$CX$9,9,FALSE),T18-HLOOKUP(V18,Masterf!$C$1:$CD$9,9,FALSE)) -> -1000 | AJ18: =IF(E18=0," ",IF(AI18>=0,$AI$5,IF(AH18>=0,$AH$5,IF(AG18>=0,$AG$5,IF(AF18>=0,$AF$5,IF(AE18>=0,$AE$5,IF(AD18>=0,$AD$5,IF(AC18>=0,$AC$5,$AB$5)))))))) -> REG | AL18: =IF(AJ18="","",AJ18) -> REG | AM18: =IF(E18=0," ",IF(AI18>=0,AI18,IF(AH18>=0,AH18,IF(AG18>=0,AG18,IF(AF18>=0,AF18,IF(AE18>=0,AE18,IF(AD18>=0,AD18,IF(AC18>=0,AC18,AC18)))))))) -> -90 | AN18: =IF(AND(H18<1922),VLOOKUP(K18,Masterh!$F$11:$P$29,11),IF(AND(H18>=1922,H18<1940),VLOOKUP(K18,Masterh!$F$11:$P$29,11),IF(AND(H18>=1940,H18<1945),VLOOKUP(K18,Masterh!$F$11:$P$29,10),IF(AND(H18>=1945,H18<1950),VLOOKUP(K18,Masterh!$F$11:$P$29,9),IF(AND(H18>=1950,H18<1955),VLOOKUP(K18,Masterh!$F$11:$P$29,8),IF(AND(H18>=1955,H18<1960),VLOOKUP(K18,Masterh!$F$11:$P$29,7),IF(AND(H18>=1960,H18<1965),VLOOKUP(K18,Masterh!$F$11:$P$29,6),IF(AND(H18>=1965,H18<1970),VLOOKUP(K18,Masterh!$F$11:$P$29,5),IF(AND(H18>=1970,H18<1975),VLOOKUP(K18,Masterh!$F$11:$P$29,4),IF(AND(H18>=1975,H18<1980),VLOOKUP(K18,Masterh!$F$11:$P$29,3),IF(AND(H18>=1980,H18<1985),VLOOKUP(K18,Masterh!$F$11:$P$29,2),"SENIOR"))))))))))) -> M65 -81 | AO18: =IF(AND(H18<1950),VLOOKUP(K18,Masterf!$F$11:$N$25,9),IF(AND(H18>=1950,H18<1955),VLOOKUP(K18,Masterf!$F$11:$N$25,8),IF(AND(H18>=1955,H18<1960),VLOOKUP(K18,Masterf!$F$11:$N$25,7),IF(AND(H18>=1960,H18<1965),VLOOKUP(K18,Masterf!$F$11:$N$25,6),IF(AND(H18>=1965,H18<1970),VLOOKUP(K18,Masterf!$F$11:$N$25,5),IF(AND(H18>=1970,H18<1975),VLOOKUP(K18,Masterf!$F$11:$N$25,4),IF(AND(H18>=1975,H18<1980),VLOOKUP(K18,Masterf!$F$11:$N$25,3),IF(AND(H18>=1980,H18<1985),VLOOKUP(K18,Masterf!$F$11:$N$25,2),"SENIOR")))))))) -> W65 -76
